Workbook

Sheet Convertisseur
A1: Convertisseur de cotes
A2: Remplis les cellules jaunes. Valeur correcte + 2 crans en dessous, avec le rayon et les outils de ta liste.
A4: Cote à convertir | B4: 5/16 | C4: ← ex. 5/16, 1 3/8, 0.3125, 7.94
A5: Unité de la cote | B5: Fraction | C5: ← Fraction, Décimal (pouces) ou mm
A6: Table (pas des outils) | B6: 1/16 | C6: ← 1/16 = table du travail
A8: Cote
A9: Cote po | B9: =IF(ISNUMBER(Calcul!$C$11),Calcul!$C$11,"Cote invalide") -> 0.3125 | C9: Cote mm | D9: =IF(ISNUMBER(Calcul!$C$11),Calcul!$C$11*25.4,"") -> 7.9375
A10: Rayon po | B10: =IF(ISNUMBER(Calcul!$C$11),Calcul!$C$11/2,"") -> 0.15625 | C10: Rayon mm | D10: =IF(ISNUMBER(Calcul!$C$11),Calcul!$C$11*25.4/2,"") -> 3.96875
A11: Vérification | B11: =IF(NOT(ISNUMBER(Calcul!$C$11)),"Cote invalide : vérifie la saisie",IF(Calcul!$C$14<1,"Plus petit que "&Convertisseur!$B$6&" po : aucun outil",IF(ABS(Calcul!$C$11*Calcul!$C$13-ROUND(Calcul!$C$11*Calcul!$C$13,0))<0.0001,"Multiple exact de "&Convertisseur!$B$6,"Pas un multiple de "&Convertisseur!$B$6&" : arrondi au cran en dessous"))) -> Multiple exact de 1/16
A13: Choix | B13: Fraction | C13: Décimal (po) | D13: mm | E13: Rayon (po) | F13: Rayon (mm) | G13: Écart vs cote (po)
A14: Valeur correcte | B14: =IF(C14<=0,"—",IF(NOT(ISNUMBER(C14)),"",IF(C14<=0,"",IF(ABS(C14*64-ROUND(C14*64,0))>0.0005,"≈ ","")&IF(INT(ROUND(C14*64,0)/64)>0,INT(ROUND(C14*64,0)/64)&IF(MOD(ROUND(C14*64,0),64)>0," ",""),"")&IF(MOD(ROUND(C14*64,0),64)>0,MOD(ROUND(C14*64,0),64)/GCD(MOD(ROUND(C14*64,0),64),64)&"/"&64/GCD(MOD(ROUND(C14*64,0),64),64),IF(ROUND(C14*64,0)=0,"0",""))&""""))) -> 5/16" | C14: =IF(ISNUMBER(Calcul!$C$11),MAX(0,(Calcul!$C$14-0)/Calcul!$C$13),0) -> 0.3125 | D14: =IF(C14<=0,"—",C14*25.4) -> 7.9375 | E14: =IF(C14<=0,"—",C14/2) -> 0.15625 | F14: =IF(C14<=0,"—",C14*25.4/2) -> 3.96875 | G14: =IF(C14<=0,"—",C14-Calcul!$C$11) -> 0
A15: 1 cran en dessous | B15: =IF(C15<=0,"—",IF(NOT(ISNUMBER(C15)),"",IF(C15<=0,"",IF(ABS(C15*64-ROUND(C15*64,0))>0.0005,"≈ ","")&IF(INT(ROUND(C15*64,0)/64)>0,INT(ROUND(C15*64,0)/64)&IF(MOD(ROUND(C15*64,0),64)>0," ",""),"")&IF(MOD(ROUND(C15*64,0),64)>0,MOD(ROUND(C15*64,0),64)/GCD(MOD(ROUND(C15*64,0),64),64)&"/"&64/GCD(MOD(ROUND(C15*64,0),64),64),IF(ROUND(C15*64,0)=0,"0",""))&""""))) -> 1/4" | C15: =IF(ISNUMBER(Calcul!$C$11),MAX(0,(Calcul!$C$14-1)/Calcul!$C$13),0) -> 0.25 | D15: =IF(C15<=0,"—",C15*25.4) -> 6.35 | E15: =IF(C15<=0,"—",C15/2) -> 0.125 | F15: =IF(C15<=0,"—",C15*25.4/2) -> 3.175 | G15: =IF(C15<=0,"—",C15-Calcul!$C$11) -> -0.0625
A16: 2 crans en dessous | B16: =IF(C16<=0,"—",IF(NOT(ISNUMBER(C16)),"",IF(C16<=0,"",IF(ABS(C16*64-ROUND(C16*64,0))>0.0005,"≈ ","")&IF(INT(ROUND(C16*64,0)/64)>0,INT(ROUND(C16*64,0)/64)&IF(MOD(ROUND(C16*64,0),64)>0," ",""),"")&IF(MOD(ROUND(C16*64,0),64)>0,MOD(ROUND(C16*64,0),64)/GCD(MOD(ROUND(C16*64,0),64),64)&"/"&64/GCD(MOD(ROUND(C16*64,0),64),64),IF(ROUND(C16*64,0)=0,"0",""))&""""))) -> 3/16" | C16: =IF(ISNUMBER(Calcul!$C$11),MAX(0,(Calcul!$C$14-2)/Calcul!$C$13),0) -> 0.1875 | D16: =IF(C16<=0,"—",C16*25.4) -> 4.7625 | E16: =IF(C16<=0,"—",C16/2) -> 0.09375 | F16: =IF(C16<=0,"—",C16*25.4/2) -> 2.38125 | G16: =IF(C16<=0,"—",C16-Calcul!$C$11) -> -0.125
A19: ="Outils de ta liste pour "&IF(C14<=0,"—",B14)&" ("&A14&")" -> Outils de ta liste pour 5/16" (Valeur correcte)
A20: =IF(C14<=0,"",COUNT(Calcul!$M$60:$M$184)&" outil(s) de ce diamètre") -> 0 outil(s) de ce diamètre
A21: N° | B21: Type | C21: Direction | D21: LOC | E21: Emplacement | F21: N° fabricant | G21: Note
A22: =IF(IFERROR(MATCH(1,Calcul!$M$60:$M$184,0),0)=0,"",INDEX('Liste outils'!$B$6:$B$130,IFERROR(MATCH(1,Calcul!$M$60:$M$184,0),0))&"") | B22: =IF(IFERROR(MATCH(1,Calcul!$M$60:$M$184,0),0)=0,"",INDEX('Liste outils'!$C$6:$C$130,IFERROR(MATCH(1,Calcul!$M$60:$M$184,0),0))&"") | C22: =IF(IFERROR(MATCH(1,Calcul!$M$60:$M$184,0),0)=0,"",INDEX('Liste outils'!$J$6:$J$130,IFERROR(MATCH(1,Calcul!$M$60:$M$184,0),0))&"") | D22: =IF(IFERROR(MATCH(1,Calcul!$M$60:$M$184,0),0)=0,"",IF(ISNUMBER(INDEX('Liste outils'!$H$6:$H$130,IFERROR(MATCH(1,Calcul!$M$60:$M$184,0),0))),IF(NOT(ISNUMBER(INDEX('Liste outils'!$H$6:$H$130,IFERROR(MATCH(1,Calcul!$M$60:$M$184,0),0)))),"",IF(NOT(ISNUMBER(INDEX('Liste outils'!$H$6:$H$130,IFERROR(MATCH(1,Calcul!$M$60:$M$184,0),0)))),"",IF(INDEX('Liste outils'!$H$6:$H$130,IFERROR(MATCH(1,Calcul!$M$60:$M$184,0),0))<=0,"",IF(ABS(INDEX('Liste outils'!$H$6:$H$130,IFERROR(MATCH(1,Calcul!$M$60:$M$184,0),0))*64-ROUND(INDEX('Liste outils'!$H$6:$H$130,IFERROR(MATCH(1,Calcul!$M$60:$M$184,0),0))*64,0))>0.0005,"≈ ","")&IF(INT(ROUND(INDEX('Liste outils'!$H$6:$H$130,IFERROR(MATCH(1,Calcul!$M$60:$M$184,0),0))*64,0)/64)>0,INT(ROUND(INDEX('Liste outils'!$H$6:$H$130,IFERROR(MATCH(1,Calcul!$M$60:$M$184,0),0))*64,0)/64)&IF(MOD(ROUND(INDEX('Liste outils'!$H$6:$H$130,IFERROR(MATCH(1,Calcul!$M$60:$M$184,0),0))*64,0),64)>0," ",""),"")&IF(MOD(ROUND(INDEX('Liste outils'!$H$6:$H$130,IFERROR(MATCH(1,Calcul!$M$60:$M$184,0),0))*64,0),64)>0,MOD(ROUND(INDEX('Liste outils'!$H$6:$H$130,IFERROR(MATCH(1,Calcul!$M$60:$M$184,0),0))*64,0),64)/GCD(MOD(ROUND(INDEX('Liste outils'!$H$6:$H$130,IFERROR(MATCH(1,Calcul!$M$60:$M$184,0),0))*64,0),64),64)&"/"&64/GCD(MOD(ROUND(INDEX('Liste outils'!$H$6:$H$130,IFERROR(MATCH(1,Calcul!$M$60:$M$184,0),0))*64,0),64),64),IF(ROUND(INDEX('Liste outils'!$H$6:$H$130,IFERROR(MATCH(1,Calcul!$M$60:$M$184,0),0))*64,0)=0,"0",""))&""""))&" · "&FIXED(INDEX('Liste outils'!$H$6:$H$130,IFERROR(MATCH(1,Calcul!$M$60:$M$184,0),0)),4,TRUE())&" po · "&FIXED(INDEX('Liste outils'!$H$6:$H$130,IFERROR(MATCH(1,Calcul!$M$60:$M$184,0),0))*25.4,3,TRUE())&" mm"),"")) | E22: =IF(IFERROR(MATCH(1,Calcul!$M$60:$M$184,0),0)=0,"",INDEX('Liste outils'!$AB$6:$AB$130,IFERROR(MATCH(1,Calcul!$M$60:$M$184,0),0))&"") | F22: =IF(IFERROR(MATCH(1,Calcul!$M$60:$M$184,0),0)=0,"",INDEX('Liste outils'!$O$6:$O$130,IFERROR(MATCH(1,Calcul!$M$60:$M$184,0),0))&"") | G22: =IF(IFERROR(MATCH(1,Calcul!$M$60:$M$184,0),0)=0,"",INDEX('Liste outils'!$AC$6:$AC$130,IFERROR(MATCH(1,Calcul!$M$60:$M$184,0),0))&"")
A23: =IF(IFERROR(MATCH(2,Calcul!$M$60:$M$184,0),0)=0,"",INDEX('Liste outils'!$B$6:$B$130,IFERROR(MATCH(2,Calcul!$M$60:$M$184,0),0))&"") | B23: =IF(IFERROR(MATCH(2,Calcul!$M$60:$M$184,0),0)=0,"",INDEX('Liste outils'!$C$6:$C$130,IFERROR(MATCH(2,Calcul!$M$60:$M$184,0),0))&"") | C23: =IF(IFERROR(MATCH(2,Calcul!$M$60:$M$184,0),0)=0,"",INDEX('Liste outils'!$J$6:$J$130,IFERROR(MATCH(2,Calcul!$M$60:$M$184,0),0))&"") | D23: =IF(IFERROR(MATCH(2,Calcul!$M$60:$M$184,0),0)=0,"",IF(ISNUMBER(INDEX('Liste outils'!$H$6:$H$130,IFERROR(MATCH(2,Calcul!$M$60:$M$184,0),0))),IF(NOT(ISNUMBER(INDEX('Liste outils'!$H$6:$H$130,IFERROR(MATCH(2,Calcul!$M$60:$M$184,0),0)))),"",IF(NOT(ISNUMBER(INDEX('Liste outils'!$H$6:$H$130,IFERROR(MATCH(2,Calcul!$M$60:$M$184,0),0)))),"",IF(INDEX('Liste outils'!$H$6:$H$130,IFERROR(MATCH(2,Calcul!$M$60:$M$184,0),0))<=0,"",IF(ABS(INDEX('Liste outils'!$H$6:$H$130,IFERROR(MATCH(2,Calcul!$M$60:$M$184,0),0))*64-ROUND(INDEX('Liste outils'!$H$6:$H$130,IFERROR(MATCH(2,Calcul!$M$60:$M$184,0),0))*64,0))>0.0005,"≈ ","")&IF(INT(ROUND(INDEX('Liste outils'!$H$6:$H$130,IFERROR(MATCH(2,Calcul!$M$60:$M$184,0),0))*64,0)/64)>0,INT(ROUND(INDEX('Liste outils'!$H$6:$H$130,IFERROR(MATCH(2,Calcul!$M$60:$M$184,0),0))*64,0)/64)&IF(MOD(ROUND(INDEX('Liste outils'!$H$6:$H$130,IFERROR(MATCH(2,Calcul!$M$60:$M$184,0),0))*64,0),64)>0," ",""),"")&IF(MOD(ROUND(INDEX('Liste outils'!$H$6:$H$130,IFERROR(MATCH(2,Calcul!$M$60:$M$184,0),0))*64,0),64)>0,MOD(ROUND(INDEX('Liste outils'!$H$6:$H$130,IFERROR(MATCH(2,Calcul!$M$60:$M$184,0),0))*64,0),64)/GCD(MOD(ROUND(INDEX('Liste outils'!$H$6:$H$130,IFERROR(MATCH(2,Calcul!$M$60:$M$184,0),0))*64,0),64),64)&"/"&64/GCD(MOD(ROUND(INDEX('Liste outils'!$H$6:$H$130,IFERROR(MATCH(2,Calcul!$M$60:$M$184,0),0))*64,0),64),64),IF(ROUND(INDEX('Liste outils'!$H$6:$H$130,IFERROR(MATCH(2,Calcul!$M$60:$M$184,0),0))*64,0)=0,"0",""))&""""))&" · "&FIXED(INDEX('Liste outils'!$H$6:$H$130,IFERROR(MATCH(2,Calcul!$M$60:$M$184,0),0)),4,TRUE())&" po · "&FIXED(INDEX('Liste outils'!$H$6:$H$130,IFERROR(MATCH(2,Calcul!$M$60:$M$184,0),0))*25.4,3,TRUE())&" mm"),"")) | E23: =IF(IFERROR(MATCH(2,Calcul!$M$60:$M$184,0),0)=0,"",INDEX('Liste outils'!$AB$6:$AB$130,IFERROR(MATCH(2,Calcul!$M$60:$M$184,0),0))&"") | F23: =IF(IFERROR(MATCH(2,Calcul!$M$60:$M$184,0),0)=0,"",INDEX('Liste outils'!$O$6:$O$130,IFERROR(MATCH(2,Calcul!$M$60:$M$184,0),0))&"") | G23: =IF(IFERROR(MATCH(2,Calcul!$M$60:$M$184,0),0)=0,"",INDEX('Liste outils'!$AC$6:$AC$130,IFERROR(MATCH(2,Calcul!$M$60:$M$184,0),0))&"")
A24: =IF(IFERROR(MATCH(3,Calcul!$M$60:$M$184,0),0)=0,"",INDEX('Liste outils'!$B$6:$B$130,IFERROR(MATCH(3,Calcul!$M$60:$M$184,0),0))&"") | B24: =IF(IFERROR(MATCH(3,Calcul!$M$60:$M$184,0),0)=0,"",INDEX('Liste outils'!$C$6:$C$130,IFERROR(MATCH(3,Calcul!$M$60:$M$184,0),0))&"") | C24: =IF(IFERROR(MATCH(3,Calcul!$M$60:$M$184,0),0)=0,"",INDEX('Liste outils'!$J$6:$J$130,IFERROR(MATCH(3,Calcul!$M$60:$M$184,0),0))&"") | D24: =IF(IFERROR(MATCH(3,Calcul!$M$60:$M$184,0),0)=0,"",IF(ISNUMBER(INDEX('Liste outils'!$H$6:$H$130,IFERROR(MATCH(3,Calcul!$M$60:$M$184,0),0))),IF(NOT(ISNUMBER(INDEX('Liste outils'!$H$6:$H$130,IFERROR(MATCH(3,Calcul!$M$60:$M$184,0),0)))),"",IF(NOT(ISNUMBER(INDEX('Liste outils'!$H$6:$H$130,IFERROR(MATCH(3,Calcul!$M$60:$M$184,0),0)))),"",IF(INDEX('Liste outils'!$H$6:$H$130,IFERROR(MATCH(3,Calcul!$M$60:$M$184,0),0))<=0,"",IF(ABS(INDEX('Liste outils'!$H$6:$H$130,IFERROR(MATCH(3,Calcul!$M$60:$M$184,0),0))*64-ROUND(INDEX('Liste outils'!$H$6:$H$130,IFERROR(MATCH(3,Calcul!$M$60:$M$184,0),0))*64,0))>0.0005,"≈ ","")&IF(INT(ROUND(INDEX('Liste outils'!$H$6:$H$130,IFERROR(MATCH(3,Calcul!$M$60:$M$184,0),0))*64,0)/64)>0,INT(ROUND(INDEX('Liste outils'!$H$6:$H$130,IFERROR(MATCH(3,Calcul!$M$60:$M$184,0),0))*64,0)/64)&IF(MOD(ROUND(INDEX('Liste outils'!$H$6:$H$130,IFERROR(MATCH(3,Calcul!$M$60:$M$184,0),0))*64,0),64)>0," ",""),"")&IF(MOD(ROUND(INDEX('Liste outils'!$H$6:$H$130,IFERROR(MATCH(3,Calcul!$M$60:$M$184,0),0))*64,0),64)>0,MOD(ROUND(INDEX('Liste outils'!$H$6:$H$130,IFERROR(MATCH(3,Calcul!$M$60:$M$184,0),0))*64,0),64)/GCD(MOD(ROUND(INDEX('Liste outils'!$H$6:$H$130,IFERROR(MATCH(3,Calcul!$M$60:$M$184,0),0))*64,0),64),64)&"/"&64/GCD(MOD(ROUND(INDEX('Liste outils'!$H$6:$H$130,IFERROR(MATCH(3,Calcul!$M$60:$M$184,0),0))*64,0),64),64),IF(ROUND(INDEX('Liste outils'!$H$6:$H$130,IFERROR(MATCH(3,Calcul!$M$60:$M$184,0),0))*64,0)=0,"0",""))&""""))&" · "&FIXED(INDEX('Liste outils'!$H$6:$H$130,IFERROR(MATCH(3,Calcul!$M$60:$M$184,0),0)),4,TRUE())&" po · "&FIXED(INDEX('Liste outils'!$H$6:$H$130,IFERROR(MATCH(3,Calcul!$M$60:$M$184,0),0))*25.4,3,TRUE())&" mm"),"")) | E24: =IF(IFERROR(MATCH(3,Calcul!$M$60:$M$184,0),0)=0,"",INDEX('Liste outils'!$AB$6:$AB$130,IFERROR(MATCH(3,Calcul!$M$60:$M$184,0),0))&"") | F24: =IF(IFERROR(MATCH(3,Calcul!$M$60:$M$184,0),0)=0,"",INDEX('Liste outils'!$O$6:$O$130,IFERROR(MATCH(3,Calcul!$M$60:$M$184,0),0))&"") | G24: =IF(IFERROR(MATCH(3,Calcul!$M$60:$M$184,0),0)=0,"",INDEX('Liste outils'!$AC$6:$AC$130,IFERROR(MATCH(3,Calcul!$M$60:$M$184,0),0))&"")
A25: =IF(IFERROR(MATCH(4,Calcul!$M$60:$M$184,0),0)=0,"",INDEX('Liste outils'!$B$6:$B$130,IFERROR(MATCH(4,Calcul!$M$60:$M$184,0),0))&"") | B25: =IF(IFERROR(MATCH(4,Calcul!$M$60:$M$184,0),0)=0,"",INDEX('Liste outils'!$C$6:$C$130,IFERROR(MATCH(4,Calcul!$M$60:$M$184,0),0))&"") | C25: =IF(IFERROR(MATCH(4,Calcul!$M$60:$M$184,0),0)=0,"",INDEX('Liste outils'!$J$6:$J$130,IFERROR(MATCH(4,Calcul!$M$60:$M$184,0),0))&"") | D25: =IF(IFERROR(MATCH(4,Calcul!$M$60:$M$184,0),0)=0,"",IF(ISNUMBER(INDEX('Liste outils'!$H$6:$H$130,IFERROR(MATCH(4,Calcul!$M$60:$M$184,0),0))),IF(NOT(ISNUMBER(INDEX('Liste outils'!$H$6:$H$130,IFERROR(MATCH(4,Calcul!$M$60:$M$184,0),0)))),"",IF(NOT(ISNUMBER(INDEX('Liste outils'!$H$6:$H$130,IFERROR(MATCH(4,Calcul!$M$60:$M$184,0),0)))),"",IF(INDEX('Liste outils'!$H$6:$H$130,IFERROR(MATCH(4,Calcul!$M$60:$M$184,0),0))<=0,"",IF(ABS(INDEX('Liste outils'!$H$6:$H$130,IFERROR(MATCH(4,Calcul!$M$60:$M$184,0),0))*64-ROUND(INDEX('Liste outils'!$H$6:$H$130,IFERROR(MATCH(4,Calcul!$M$60:$M$184,0),0))*64,0))>0.0005,"≈ ","")&IF(INT(ROUND(INDEX('Liste outils'!$H$6:$H$130,IFERROR(MATCH(4,Calcul!$M$60:$M$184,0),0))*64,0)/64)>0,INT(ROUND(INDEX('Liste outils'!$H$6:$H$130,IFERROR(MATCH(4,Calcul!$M$60:$M$184,0),0))*64,0)/64)&IF(MOD(ROUND(INDEX('Liste outils'!$H$6:$H$130,IFERROR(MATCH(4,Calcul!$M$60:$M$184,0),0))*64,0),64)>0," ",""),"")&IF(MOD(ROUND(INDEX('Liste outils'!$H$6:$H$130,IFERROR(MATCH(4,Calcul!$M$60:$M$184,0),0))*64,0),64)>0,MOD(ROUND(INDEX('Liste outils'!$H$6:$H$130,IFERROR(MATCH(4,Calcul!$M$60:$M$184,0),0))*64,0),64)/GCD(MOD(ROUND(INDEX('Liste outils'!$H$6:$H$130,IFERROR(MATCH(4,Calcul!$M$60:$M$184,0),0))*64,0),64),64)&"/"&64/GCD(MOD(ROUND(INDEX('Liste outils'!$H$6:$H$130,IFERROR(MATCH(4,Calcul!$M$60:$M$184,0),0))*64,0),64),64),IF(ROUND(INDEX('Liste outils'!$H$6:$H$130,IFERROR(MATCH(4,Calcul!$M$60:$M$184,0),0))*64,0)=0,"0",""))&""""))&" · "&FIXED(INDEX('Liste outils'!$H$6:$H$130,IFERROR(MATCH(4,Calcul!$M$60:$M$184,0),0)),4,TRUE())&" po · "&FIXED(INDEX('Liste outils'!$H$6:$H$130,IFERROR(MATCH(4,Calcul!$M$60:$M$184,0),0))*25.4,3,TRUE())&" mm"),"")) | E25: =IF(IFERROR(MATCH(4,Calcul!$M$60:$M$184,0),0)=0,"",INDEX('Liste outils'!$AB$6:$AB$130,IFERROR(MATCH(4,Calcul!$M$60:$M$184,0),0))&"") | F25: =IF(IFERROR(MATCH(4,Calcul!$M$60:$M$184,0),0)=0,"",INDEX('Liste outils'!$O$6:$O$130,IFERROR(MATCH(4,Calcul!$M$60:$M$184,0),0))&"") | G25: =IF(IFERROR(MATCH(4,Calcul!$M$60:$M$184,0),0)=0,"",INDEX('Liste outils'!$AC$6:$AC$130,IFERROR(MATCH(4,Calcul!$M$60:$M$184,0),0))&"")
A26: =IF(IFERROR(MATCH(5,Calcul!$M$60:$M$184,0),0)=0,"",INDEX('Liste outils'!$B$6:$B$130,IFERROR(MATCH(5,Calcul!$M$60:$M$184,0),0))&"") | B26: =IF(IFERROR(MATCH(5,Calcul!$M$60:$M$184,0),0)=0,"",INDEX('Liste outils'!$C$6:$C$130,IFERROR(MATCH(5,Calcul!$M$60:$M$184,0),0))&"") | C26: =IF(IFERROR(MATCH(5,Calcul!$M$60:$M$184,0),0)=0,"",INDEX('Liste outils'!$J$6:$J$130,IFERROR(MATCH(5,Calcul!$M$60:$M$184,0),0))&"") | D26: =IF(IFERROR(MATCH(5,Calcul!$M$60:$M$184,0),0)=0,"",IF(ISNUMBER(INDEX('Liste outils'!$H$6:$H$130,IFERROR(MATCH(5,Calcul!$M$60:$M$184,0),0))),IF(NOT(ISNUMBER(INDEX('Liste outils'!$H$6:$H$130,IFERROR(MATCH(5,Calcul!$M$60:$M$184,0),0)))),"",IF(NOT(ISNUMBER(INDEX('Liste outils'!$H$6:$H$130,IFERROR(MATCH(5,Calcul!$M$60:$M$184,0),0)))),"",IF(INDEX('Liste outils'!$H$6:$H$130,IFERROR(MATCH(5,Calcul!$M$60:$M$184,0),0))<=0,"",IF(ABS(INDEX('Liste outils'!$H$6:$H$130,IFERROR(MATCH(5,Calcul!$M$60:$M$184,0),0))*64-ROUND(INDEX('Liste outils'!$H$6:$H$130,IFERROR(MATCH(5,Calcul!$M$60:$M$184,0),0))*64,0))>0.0005,"≈ ","")&IF(INT(ROUND(INDEX('Liste outils'!$H$6:$H$130,IFERROR(MATCH(5,Calcul!$M$60:$M$184,0),0))*64,0)/64)>0,INT(ROUND(INDEX('Liste outils'!$H$6:$H$130,IFERROR(MATCH(5,Calcul!$M$60:$M$184,0),0))*64,0)/64)&IF(MOD(ROUND(INDEX('Liste outils'!$H$6:$H$130,IFERROR(MATCH(5,Calcul!$M$60:$M$184,0),0))*64,0),64)>0," ",""),"")&IF(MOD(ROUND(INDEX('Liste outils'!$H$6:$H$130,IFERROR(MATCH(5,Calcul!$M$60:$M$184,0),0))*64,0),64)>0,MOD(ROUND(INDEX('Liste outils'!$H$6:$H$130,IFERROR(MATCH(5,Calcul!$M$60:$M$184,0),0))*64,0),64)/GCD(MOD(ROUND(INDEX('Liste outils'!$H$6:$H$130,IFERROR(MATCH(5,Calcul!$M$60:$M$184,0),0))*64,0),64),64)&"/"&64/GCD(MOD(ROUND(INDEX('Liste outils'!$H$6:$H$130,IFERROR(MATCH(5,Calcul!$M$60:$M$184,0),0))*64,0),64),64),IF(ROUND(INDEX('Liste outils'!$H$6:$H$130,IFERROR(MATCH(5,Calcul!$M$60:$M$184,0),0))*64,0)=0,"0",""))&""""))&" · "&FIXED(INDEX('Liste outils'!$H$6:$H$130,IFERROR(MATCH(5,Calcul!$M$60:$M$184,0),0)),4,TRUE())&" po · "&FIXED(INDEX('Liste outils'!$H$6:$H$130,IFERROR(MATCH(5,Calcul!$M$60:$M$184,0),0))*25.4,3,TRUE())&" mm"),"")) | E26: =IF(IFERROR(MATCH(5,Calcul!$M$60:$M$184,0),0)=0,"",INDEX('Liste outils'!$AB$6:$AB$130,IFERROR(MATCH(5,Calcul!$M$60:$M$184,0),0))&"") | F26: =IF(IFERROR(MATCH(5,Calcul!$M$60:$M$184,0),0)=0,"",INDEX('Liste outils'!$O$6:$O$130,IFERROR(MATCH(5,Calcul!$M$60:$M$184,0),0))&"") | G26: =IF(IFERROR(MATCH(5,Calcul!$M$60:$M$184,0),0)=0,"",INDEX('Liste outils'!$AC$6:$AC$130,IFERROR(MATCH(5,Calcul!$M$60:$M$184,0),0))&"")
A27: =IF(IFERROR(MATCH(6,Calcul!$M$60:$M$184,0),0)=0,"",INDEX('Liste outils'!$B$6:$B$130,IFERROR(MATCH(6,Calcul!$M$60:$M$184,0),0))&"") | B27: =IF(IFERROR(MATCH(6,Calcul!$M$60:$M$184,0),0)=0,"",INDEX('Liste outils'!$C$6:$C$130,IFERROR(MATCH(6,Calcul!$M$60:$M$184,0),0))&"") | C27: =IF(IFERROR(MATCH(6,Calcul!$M$60:$M$184,0),0)=0,"",INDEX('Liste outils'!$J$6:$J$130,IFERROR(MATCH(6,Calcul!$M$60:$M$184,0),0))&"") | D27: =IF(IFERROR(MATCH(6,Calcul!$M$60:$M$184,0),0)=0,"",IF(ISNUMBER(INDEX('Liste outils'!$H$6:$H$130,IFERROR(MATCH(6,Calcul!$M$60:$M$184,0),0))),IF(NOT(ISNUMBER(INDEX('Liste outils'!$H$6:$H$130,IFERROR(MATCH(6,Calcul!$M$60:$M$184,0),0)))),"",IF(NOT(ISNUMBER(INDEX('Liste outils'!$H$6:$H$130,IFERROR(MATCH(6,Calcul!$M$60:$M$184,0),0)))),"",IF(INDEX('Liste outils'!$H$6:$H$130,IFERROR(MATCH(6,Calcul!$M$60:$M$184,0),0))<=0,"",IF(ABS(INDEX('Liste outils'!$H$6:$H$130,IFERROR(MATCH(6,Calcul!$M$60:$M$184,0),0))*64-ROUND(INDEX('Liste outils'!$H$6:$H$130,IFERROR(MATCH(6,Calcul!$M$60:$M$184,0),0))*64,0))>0.0005,"≈ ","")&IF(INT(ROUND(INDEX('Liste outils'!$H$6:$H$130,IFERROR(MATCH(6,Calcul!$M$60:$M$184,0),0))*64,0)/64)>0,INT(ROUND(INDEX('Liste outils'!$H$6:$H$130,IFERROR(MATCH(6,Calcul!$M$60:$M$184,0),0))*64,0)/64)&IF(MOD(ROUND(INDEX('Liste outils'!$H$6:$H$130,IFERROR(MATCH(6,Calcul!$M$60:$M$184,0),0))*64,0),64)>0," ",""),"")&IF(MOD(ROUND(INDEX('Liste outils'!$H$6:$H$130,IFERROR(MATCH(6,Calcul!$M$60:$M$184,0),0))*64,0),64)>0,MOD(ROUND(INDEX('Liste outils'!$H$6:$H$130,IFERROR(MATCH(6,Calcul!$M$60:$M$184,0),0))*64,0),64)/GCD(MOD(ROUND(INDEX('Liste outils'!$H$6:$H$130,IFERROR(MATCH(6,Calcul!$M$60:$M$184,0),0))*64,0),64),64)&"/"&64/GCD(MOD(ROUND(INDEX('Liste outils'!$H$6:$H$130,IFERROR(MATCH(6,Calcul!$M$60:$M$184,0),0))*64,0),64),64),IF(ROUND(INDEX('Liste outils'!$H$6:$H$130,IFERROR(MATCH(6,Calcul!$M$60:$M$184,0),0))*64,0)=0,"0",""))&""""))&" · "&FIXED(INDEX('Liste outils'!$H$6:$H$130,IFERROR(MATCH(6,Calcul!$M$60:$M$184,0),0)),4,TRUE())&" po · "&FIXED(INDEX('Liste outils'!$H$6:$H$130,IFERROR(MATCH(6,Calcul!$M$60:$M$184,0),0))*25.4,3,TRUE())&" mm"),"")) | E27: =IF(IFERROR(MATCH(6,Calcul!$M$60:$M$184,0),0)=0,"",INDEX('Liste outils'!$AB$6:$AB$130,IFERROR(MATCH(6,Calcul!$M$60:$M$184,0),0))&"") | F27: =IF(IFERROR(MATCH(6,Calcul!$M$60:$M$184,0),0)=0,"",INDEX('Liste outils'!$O$6:$O$130,IFERROR(MATCH(6,Calcul!$M$60:$M$184,0),0))&"") | G27: =IF(IFERROR(MATCH(6,Calcul!$M$60:$M$184,0),0)=0,"",INDEX('Liste outils'!$AC$6:$AC$130,IFERROR(MATCH(6,Calcul!$M$60:$M$184,0),0))&"")
A28: =IF(IFERROR(MATCH(7,Calcul!$M$60:$M$184,0),0)=0,"",INDEX('Liste outils'!$B$6:$B$130,IFERROR(MATCH(7,Calcul!$M$60:$M$184,0),0))&"") | B28: =IF(IFERROR(MATCH(7,Calcul!$M$60:$M$184,0),0)=0,"",INDEX('Liste outils'!$C$6:$C$130,IFERROR(MATCH(7,Calcul!$M$60:$M$184,0),0))&"") | C28: =IF(IFERROR(MATCH(7,Calcul!$M$60:$M$184,0),0)=0,"",INDEX('Liste outils'!$J$6:$J$130,IFERROR(MATCH(7,Calcul!$M$60:$M$184,0),0))&"") | D28: =IF(IFERROR(MATCH(7,Calcul!$M$60:$M$184,0),0)=0,"",IF(ISNUMBER(INDEX('Liste outils'!$H$6:$H$130,IFERROR(MATCH(7,Calcul!$M$60:$M$184,0),0))),IF(NOT(ISNUMBER(INDEX('Liste outils'!$H$6:$H$130,IFERROR(MATCH(7,Calcul!$M$60:$M$184,0),0)))),"",IF(NOT(ISNUMBER(INDEX('Liste outils'!$H$6:$H$130,IFERROR(MATCH(7,Calcul!$M$60:$M$184,0),0)))),"",IF(INDEX('Liste outils'!$H$6:$H$130,IFERROR(MATCH(7,Calcul!$M$60:$M$184,0),0))<=0,"",IF(ABS(INDEX('Liste outils'!$H$6:$H$130,IFERROR(MATCH(7,Calcul!$M$60:$M$184,0),0))*64-ROUND(INDEX('Liste outils'!$H$6:$H$130,IFERROR(MATCH(7,Calcul!$M$60:$M$184,0),0))*64,0))>0.0005,"≈ ","")&IF(INT(ROUND(INDEX('Liste outils'!$H$6:$H$130,IFERROR(MATCH(7,Calcul!$M$60:$M$184,0),0))*64,0)/64)>0,INT(ROUND(INDEX('Liste outils'!$H$6:$H$130,IFERROR(MATCH(7,Calcul!$M$60:$M$184,0),0))*64,0)/64)&IF(MOD(ROUND(INDEX('Liste outils'!$H$6:$H$130,IFERROR(MATCH(7,Calcul!$M$60:$M$184,0),0))*64,0),64)>0," ",""),"")&IF(MOD(ROUND(INDEX('Liste outils'!$H$6:$H$130,IFERROR(MATCH(7,Calcul!$M$60:$M$184,0),0))*64,0),64)>0,MOD(ROUND(INDEX('Liste outils'!$H$6:$H$130,IFERROR(MATCH(7,Calcul!$M$60:$M$184,0),0))*64,0),64)/GCD(MOD(ROUND(INDEX('Liste outils'!$H$6:$H$130,IFERROR(MATCH(7,Calcul!$M$60:$M$184,0),0))*64,0),64),64)&"/"&64/GCD(MOD(ROUND(INDEX('Liste outils'!$H$6:$H$130,IFERROR(MATCH(7,Calcul!$M$60:$M$184,0),0))*64,0),64),64),IF(ROUND(INDEX('Liste outils'!$H$6:$H$130,IFERROR(MATCH(7,Calcul!$M$60:$M$184,0),0))*64,0)=0,"0",""))&""""))&" · "&FIXED(INDEX('Liste outils'!$H$6:$H$130,IFERROR(MATCH(7,Calcul!$M$60:$M$184,0),0)),4,TRUE())&" po · "&FIXED(INDEX('Liste outils'!$H$6:$H$130,IFERROR(MATCH(7,Calcul!$M$60:$M$184,0),0))*25.4,3,TRUE())&" mm"),"")) | E28: =IF(IFERROR(MATCH(7,Calcul!$M$60:$M$184,0),0)=0,"",INDEX('Liste outils'!$AB$6:$AB$130,IFERROR(MATCH(7,Calcul!$M$60:$M$184,0),0))&"") | F28: =IF(IFERROR(MATCH(7,Calcul!$M$60:$M$184,0),0)=0,"",INDEX('Liste outils'!$O$6:$O$130,IFERROR(MATCH(7,Calcul!$M$60:$M$184,0),0))&"") | G28: =IF(IFERROR(MATCH(7,Calcul!$M$60:$M$184,0),0)=0,"",INDEX('Liste outils'!$AC$6:$AC$130,IFERROR(MATCH(7,Calcul!$M$60:$M$184,0),0))&"")
A29: =IF(IFERROR(MATCH(8,Calcul!$M$60:$M$184,0),0)=0,"",INDEX('Liste outils'!$B$6:$B$130,IFERROR(MATCH(8,Calcul!$M$60:$M$184,0),0))&"") | B29: =IF(IFERROR(MATCH(8,Calcul!$M$60:$M$184,0),0)=0,"",INDEX('Liste outils'!$C$6:$C$130,IFERROR(MATCH(8,Calcul!$M$60:$M$184,0),0))&"") | C29: =IF(IFERROR(MATCH(8,Calcul!$M$60:$M$184,0),0)=0,"",INDEX('Liste outils'!$J$6:$J$130,IFERROR(MATCH(8,Calcul!$M$60:$M$184,0),0))&"") | D29: =IF(IFERROR(MATCH(8,Calcul!$M$60:$M$184,0),0)=0,"",IF(ISNUMBER(INDEX('Liste outils'!$H$6:$H$130,IFERROR(MATCH(8,Calcul!$M$60:$M$184,0),0))),IF(NOT(ISNUMBER(INDEX('Liste outils'!$H$6:$H$130,IFERROR(MATCH(8,Calcul!$M$60:$M$184,0),0)))),"",IF(NOT(ISNUMBER(INDEX('Liste outils'!$H$6:$H$130,IFERROR(MATCH(8,Calcul!$M$60:$M$184,0),0)))),"",IF(INDEX('Liste outils'!$H$6:$H$130,IFERROR(MATCH(8,Calcul!$M$60:$M$184,0),0))<=0,"",IF(ABS(INDEX('Liste outils'!$H$6:$H$130,IFERROR(MATCH(8,Calcul!$M$60:$M$184,0),0))*64-ROUND(INDEX('Liste outils'!$H$6:$H$130,IFERROR(MATCH(8,Calcul!$M$60:$M$184,0),0))*64,0))>0.0005,"≈ ","")&IF(INT(ROUND(INDEX('Liste outils'!$H$6:$H$130,IFERROR(MATCH(8,Calcul!$M$60:$M$184,0),0))*64,0)/64)>0,INT(ROUND(INDEX('Liste outils'!$H$6:$H$130,IFERROR(MATCH(8,Calcul!$M$60:$M$184,0),0))*64,0)/64)&IF(MOD(ROUND(INDEX('Liste outils'!$H$6:$H$130,IFERROR(MATCH(8,Calcul!$M$60:$M$184,0),0))*64,0),64)>0," ",""),"")&IF(MOD(ROUND(INDEX('Liste outils'!$H$6:$H$130,IFERROR(MATCH(8,Calcul!$M$60:$M$184,0),0))*64,0),64)>0,MOD(ROUND(INDEX('Liste outils'!$H$6:$H$130,IFERROR(MATCH(8,Calcul!$M$60:$M$184,0),0))*64,0),64)/GCD(MOD(ROUND(INDEX('Liste outils'!$H$6:$H$130,IFERROR(MATCH(8,Calcul!$M$60:$M$184,0),0))*64,0),64),64)&"/"&64/GCD(MOD(ROUND(INDEX('Liste outils'!$H$6:$H$130,IFERROR(MATCH(8,Calcul!$M$60:$M$184,0),0))*64,0),64),64),IF(ROUND(INDEX('Liste outils'!$H$6:$H$130,IFERROR(MATCH(8,Calcul!$M$60:$M$184,0),0))*64,0)=0,"0",""))&""""))&" · "&FIXED(INDEX('Liste outils'!$H$6:$H$130,IFERROR(MATCH(8,Calcul!$M$60:$M$184,0),0)),4,TRUE())&" po · "&FIXED(INDEX('Liste outils'!$H$6:$H$130,IFERROR(MATCH(8,Calcul!$M$60:$M$184,0),0))*25.4,3,TRUE())&" mm"),"")) | E29: =IF(IFERROR(MATCH(8,Calcul!$M$60:$M$184,0),0)=0,"",INDEX('Liste outils'!$AB$6:$AB$130,IFERROR(MATCH(8,Calcul!$M$60:$M$184,0),0))&"") | F29: =IF(IFERROR(MATCH(8,Calcul!$M$60:$M$184,0),0)=0,"",INDEX('Liste outils'!$O$6:$O$130,IFERROR(MATCH(8,Calcul!$M$60:$M$184,0),0))&"") | G29: =IF(IFERROR(MATCH(8,Calcul!$M$60:$M$184,0),0)=0,"",INDEX('Liste outils'!$AC$6:$AC$130,IFERROR(MATCH(8,Calcul!$M$60:$M$184,0),0))&"")
A30: =IF(IFERROR(MATCH(9,Calcul!$M$60:$M$184,0),0)=0,"",INDEX('Liste outils'!$B$6:$B$130,IFERROR(MATCH(9,Calcul!$M$60:$M$184,0),0))&"") | B30: =IF(IFERROR(MATCH(9,Calcul!$M$60:$M$184,0),0)=0,"",INDEX('Liste outils'!$C$6:$C$130,IFERROR(MATCH(9,Calcul!$M$60:$M$184,0),0))&"") | C30: =IF(IFERROR(MATCH(9,Calcul!$M$60:$M$184,0),0)=0,"",INDEX('Liste outils'!$J$6:$J$130,IFERROR(MATCH(9,Calcul!$M$60:$M$184,0),0))&"") | D30: =IF(IFERROR(MATCH(9,Calcul!$M$60:$M$184,0),0)=0,"",IF(ISNUMBER(INDEX('Liste outils'!$H$6:$H$130,IFERROR(MATCH(9,Calcul!$M$60:$M$184,0),0))),IF(NOT(ISNUMBER(INDEX('Liste outils'!$H$6:$H$130,IFERROR(MATCH(9,Calcul!$M$60:$M$184,0),0)))),"",IF(NOT(ISNUMBER(INDEX('Liste outils'!$H$6:$H$130,IFERROR(MATCH(9,Calcul!$M$60:$M$184,0),0)))),"",IF(INDEX('Liste outils'!$H$6:$H$130,IFERROR(MATCH(9,Calcul!$M$60:$M$184,0),0))<=0,"",IF(ABS(INDEX('Liste outils'!$H$6:$H$130,IFERROR(MATCH(9,Calcul!$M$60:$M$184,0),0))*64-ROUND(INDEX('Liste outils'!$H$6:$H$130,IFERROR(MATCH(9,Calcul!$M$60:$M$184,0),0))*64,0))>0.0005,"≈ ","")&IF(INT(ROUND(INDEX('Liste outils'!$H$6:$H$130,IFERROR(MATCH(9,Calcul!$M$60:$M$184,0),0))*64,0)/64)>0,INT(ROUND(INDEX('Liste outils'!$H$6:$H$130,IFERROR(MATCH(9,Calcul!$M$60:$M$184,0),0))*64,0)/64)&IF(MOD(ROUND(INDEX('Liste outils'!$H$6:$H$130,IFERROR(MATCH(9,Calcul!$M$60:$M$184,0),0))*64,0),64)>0," ",""),"")&IF(MOD(ROUND(INDEX('Liste outils'!$H$6:$H$130,IFERROR(MATCH(9,Calcul!$M$60:$M$184,0),0))*64,0),64)>0,MOD(ROUND(INDEX('Liste outils'!$H$6:$H$130,IFERROR(MATCH(9,Calcul!$M$60:$M$184,0),0))*64,0),64)/GCD(MOD(ROUND(INDEX('Liste outils'!$H$6:$H$130,IFERROR(MATCH(9,Calcul!$M$60:$M$184,0),0))*64,0),64),64)&"/"&64/GCD(MOD(ROUND(INDEX('Liste outils'!$H$6:$H$130,IFERROR(MATCH(9,Calcul!$M$60:$M$184,0),0))*64,0),64),64),IF(ROUND(INDEX('Liste outils'!$H$6:$H$130,IFERROR(MATCH(9,Calcul!$M$60:$M$184,0),0))*64,0)=0,"0",""))&""""))&" · "&FIXED(INDEX('Liste outils'!$H$6:$H$130,IFERROR(MATCH(9,Calcul!$M$60:$M$184,0),0)),4,TRUE())&" po · "&FIXED(INDEX('Liste outils'!$H$6:$H$130,IFERROR(MATCH(9,Calcul!$M$60:$M$184,0),0))*25.4,3,TRUE())&" mm"),"")) | E30: =IF(IFERROR(MATCH(9,Calcul!$M$60:$M$184,0),0)=0,"",INDEX('Liste outils'!$AB$6:$AB$130,IFERROR(MATCH(9,Calcul!$M$60:$M$184,0),0))&"") | F30: =IF(IFERROR(MATCH(9,Calcul!$M$60:$M$184,0),0)=0,"",INDEX('Liste outils'!$O$6:$O$130,IFERROR(MATCH(9,Calcul!$M$60:$M$184,0),0))&"") | G30: =IF(IFERROR(MATCH(9,Calcul!$M$60:$M$184,0),0)=0,"",INDEX('Liste outils'!$AC$6:$AC$130,IFERROR(MATCH(9,Calcul!$M$60:$M$184,0),0))&"")
A31: =IF(IFERROR(MATCH(10,Calcul!$M$60:$M$184,0),0)=0,"",INDEX('Liste outils'!$B$6:$B$130,IFERROR(MATCH(10,Calcul!$M$60:$M$184,0),0))&"") | B31: =IF(IFERROR(MATCH(10,Calcul!$M$60:$M$184,0),0)=0,"",INDEX('Liste outils'!$C$6:$C$130,IFERROR(MATCH(10,Calcul!$M$60:$M$184,0),0))&"") | C31: =IF(IFERROR(MATCH(10,Calcul!$M$60:$M$184,0),0)=0,"",INDEX('Liste outils'!$J$6:$J$130,IFERROR(MATCH(10,Calcul!$M$60:$M$184,0),0))&"") | D31: =IF(IFERROR(MATCH(10,Calcul!$M$60:$M$184,0),0)=0,"",IF(ISNUMBER(INDEX('Liste outils'!$H$6:$H$130,IFERROR(MATCH(10,Calcul!$M$60:$M$184,0),0))),IF(NOT(ISNUMBER(INDEX('Liste outils'!$H$6:$H$130,IFERROR(MATCH(10,Calcul!$M$60:$M$184,0),0)))),"",IF(NOT(ISNUMBER(INDEX('Liste outils'!$H$6:$H$130,IFERROR(MATCH(10,Calcul!$M$60:$M$184,0),0)))),"",IF(INDEX('Liste outils'!$H$6:$H$130,IFERROR(MATCH(10,Calcul!$M$60:$M$184,0),0))<=0,"",IF(ABS(INDEX('Liste outils'!$H$6:$H$130,IFERROR(MATCH(10,Calcul!$M$60:$M$184,0),0))*64-ROUND(INDEX('Liste outils'!$H$6:$H$130,IFERROR(MATCH(10,Calcul!$M$60:$M$184,0),0))*64,0))>0.0005,"≈ ","")&IF(INT(ROUND(INDEX('Liste outils'!$H$6:$H$130,IFERROR(MATCH(10,Calcul!$M$60:$M$184,0),0))*64,0)/64)>0,INT(ROUND(INDEX('Liste outils'!$H$6:$H$130,IFERROR(MATCH(10,Calcul!$M$60:$M$184,0),0))*64,0)/64)&IF(MOD(ROUND(INDEX('Liste outils'!$H$6:$H$130,IFERROR(MATCH(10,Calcul!$M$60:$M$184,0),0))*64,0),64)>0," ",""),"")&IF(MOD(ROUND(INDEX('Liste outils'!$H$6:$H$130,IFERROR(MATCH(10,Calcul!$M$60:$M$184,0),0))*64,0),64)>0,MOD(ROUND(INDEX('Liste outils'!$H$6:$H$130,IFERROR(MATCH(10,Calcul!$M$60:$M$184,0),0))*64,0),64)/GCD(MOD(ROUND(INDEX('Liste outils'!$H$6:$H$130,IFERROR(MATCH(10,Calcul!$M$60:$M$184,0),0))*64,0),64),64)&"/"&64/GCD(MOD(ROUND(INDEX('Liste outils'!$H$6:$H$130,IFERROR(MATCH(10,Calcul!$M$60:$M$184,0),0))*64,0),64),64),IF(ROUND(INDEX('Liste outils'!$H$6:$H$130,IFERROR(MATCH(10,Calcul!$M$60:$M$184,0),0))*64,0)=0,"0",""))&""""))&" · "&FIXED(INDEX('Liste outils'!$H$6:$H$130,IFERROR(MATCH(10,Calcul!$M$60:$M$184,0),0)),4,TRUE())&" po · "&FIXED(INDEX('Liste outils'!$H$6:$H$130,IFERROR(MATCH(10,Calcul!$M$60:$M$184,0),0))*25.4,3,TRUE())&" mm"),"")) | E31: =IF(IFERROR(MATCH(10,Calcul!$M$60:$M$184,0),0)=0,"",INDEX('Liste outils'!$AB$6:$AB$130,IFERROR(MATCH(10,Calcul!$M$60:$M$184,0),0))&"") | F31: =IF(IFERROR(MATCH(10,Calcul!$M$60:$M$184,0),0)=0,"",INDEX('Liste outils'!$O$6:$O$130,IFERROR(MATCH(10,Calcul!$M$60:$M$184,0),0))&"") | G31: =IF(IFERROR(MATCH(10,Calcul!$M$60:$M$184,0),0)=0,"",INDEX('Liste outils'!$AC$6:$AC$130,IFERROR(MATCH(10,Calcul!$M$60:$M$184,0),0))&"")
A32: =IF(IFERROR(MATCH(11,Calcul!$M$60:$M$184,0),0)=0,"",INDEX('Liste outils'!$B$6:$B$130,IFERROR(MATCH(11,Calcul!$M$60:$M$184,0),0))&"") | B32: =IF(IFERROR(MATCH(11,Calcul!$M$60:$M$184,0),0)=0,"",INDEX('Liste outils'!$C$6:$C$130,IFERROR(MATCH(11,Calcul!$M$60:$M$184,0),0))&"") | C32: =IF(IFERROR(MATCH(11,Calcul!$M$60:$M$184,0),0)=0,"",INDEX('Liste outils'!$J$6:$J$130,IFERROR(MATCH(11,Calcul!$M$60:$M$184,0),0))&"") | D32: =IF(IFERROR(MATCH(11,Calcul!$M$60:$M$184,0),0)=0,"",IF(ISNUMBER(INDEX('Liste outils'!$H$6:$H$130,IFERROR(MATCH(11,Calcul!$M$60:$M$184,0),0))),IF(NOT(ISNUMBER(INDEX('Liste outils'!$H$6:$H$130,IFERROR(MATCH(11,Calcul!$M$60:$M$184,0),0)))),"",IF(NOT(ISNUMBER(INDEX('Liste outils'!$H$6:$H$130,IFERROR(MATCH(11,Calcul!$M$60:$M$184,0),0)))),"",IF(INDEX('Liste outils'!$H$6:$H$130,IFERROR(MATCH(11,Calcul!$M$60:$M$184,0),0))<=0,"",IF(ABS(INDEX('Liste outils'!$H$6:$H$130,IFERROR(MATCH(11,Calcul!$M$60:$M$184,0),0))*64-ROUND(INDEX('Liste outils'!$H$6:$H$130,IFERROR(MATCH(11,Calcul!$M$60:$M$184,0),0))*64,0))>0.0005,"≈ ","")&IF(INT(ROUND(INDEX('Liste outils'!$H$6:$H$130,IFERROR(MATCH(11,Calcul!$M$60:$M$184,0),0))*64,0)/64)>0,INT(ROUND(INDEX('Liste outils'!$H$6:$H$130,IFERROR(MATCH(11,Calcul!$M$60:$M$184,0),0))*64,0)/64)&IF(MOD(ROUND(INDEX('Liste outils'!$H$6:$H$130,IFERROR(MATCH(11,Calcul!$M$60:$M$184,0),0))*64,0),64)>0," ",""),"")&IF(MOD(ROUND(INDEX('Liste outils'!$H$6:$H$130,IFERROR(MATCH(11,Calcul!$M$60:$M$184,0),0))*64,0),64)>0,MOD(ROUND(INDEX('Liste outils'!$H$6:$H$130,IFERROR(MATCH(11,Calcul!$M$60:$M$184,0),0))*64,0),64)/GCD(MOD(ROUND(INDEX('Liste outils'!$H$6:$H$130,IFERROR(MATCH(11,Calcul!$M$60:$M$184,0),0))*64,0),64),64)&"/"&64/GCD(MOD(ROUND(INDEX('Liste outils'!$H$6:$H$130,IFERROR(MATCH(11,Calcul!$M$60:$M$184,0),0))*64,0),64),64),IF(ROUND(INDEX('Liste outils'!$H$6:$H$130,IFERROR(MATCH(11,Calcul!$M$60:$M$184,0),0))*64,0)=0,"0",""))&""""))&" · "&FIXED(INDEX('Liste outils'!$H$6:$H$130,IFERROR(MATCH(11,Calcul!$M$60:$M$184,0),0)),4,TRUE())&" po · "&FIXED(INDEX('Liste outils'!$H$6:$H$130,IFERROR(MATCH(11,Calcul!$M$60:$M$184,0),0))*25.4,3,TRUE())&" mm"),"")) | E32: =IF(IFERROR(MATCH(11,Calcul!$M$60:$M$184,0),0)=0,"",INDEX('Liste outils'!$AB$6:$AB$130,IFERROR(MATCH(11,Calcul!$M$60:$M$184,0),0))&"") | F32: =IF(IFERROR(MATCH(11,Calcul!$M$60:$M$184,0),0)=0,"",INDEX('Liste outils'!$O$6:$O$130,IFERROR(MATCH(11,Calcul!$M$60:$M$184,0),0))&"") | G32: =IF(IFERROR(MATCH(11,Calcul!$M$60:$M$184,0),0)=0,"",INDEX('Liste outils'!$AC$6:$AC$130,IFERROR(MATCH(11,Calcul!$M$60:$M$184,0),0))&"")
A33: =IF(IFERROR(MATCH(12,Calcul!$M$60:$M$184,0),0)=0,"",INDEX('Liste outils'!$B$6:$B$130,IFERROR(MATCH(12,Calcul!$M$60:$M$184,0),0))&"") | B33: =IF(IFERROR(MATCH(12,Calcul!$M$60:$M$184,0),0)=0,"",INDEX('Liste outils'!$C$6:$C$130,IFERROR(MATCH(12,Calcul!$M$60:$M$184,0),0))&"") | C33: =IF(IFERROR(MATCH(12,Calcul!$M$60:$M$184,0),0)=0,"",INDEX('Liste outils'!$J$6:$J$130,IFERROR(MATCH(12,Calcul!$M$60:$M$184,0),0))&"") | D33: =IF(IFERROR(MATCH(12,Calcul!$M$60:$M$184,0),0)=0,"",IF(ISNUMBER(INDEX('Liste outils'!$H$6:$H$130,IFERROR(MATCH(12,Calcul!$M$60:$M$184,0),0))),IF(NOT(ISNUMBER(INDEX('Liste outils'!$H$6:$H$130,IFERROR(MATCH(12,Calcul!$M$60:$M$184,0),0)))),"",IF(NOT(ISNUMBER(INDEX('Liste outils'!$H$6:$H$130,IFERROR(MATCH(12,Calcul!$M$60:$M$184,0),0)))),"",IF(INDEX('Liste outils'!$H$6:$H$130,IFERROR(MATCH(12,Calcul!$M$60:$M$184,0),0))<=0,"",IF(ABS(INDEX('Liste outils'!$H$6:$H$130,IFERROR(MATCH(12,Calcul!$M$60:$M$184,0),0))*64-ROUND(INDEX('Liste outils'!$H$6:$H$130,IFERROR(MATCH(12,Calcul!$M$60:$M$184,0),0))*64,0))>0.0005,"≈ ","")&IF(INT(ROUND(INDEX('Liste outils'!$H$6:$H$130,IFERROR(MATCH(12,Calcul!$M$60:$M$184,0),0))*64,0)/64)>0,INT(ROUND(INDEX('Liste outils'!$H$6:$H$130,IFERROR(MATCH(12,Calcul!$M$60:$M$184,0),0))*64,0)/64)&IF(MOD(ROUND(INDEX('Liste outils'!$H$6:$H$130,IFERROR(MATCH(12,Calcul!$M$60:$M$184,0),0))*64,0),64)>0," ",""),"")&IF(MOD(ROUND(INDEX('Liste outils'!$H$6:$H$130,IFERROR(MATCH(12,Calcul!$M$60:$M$184,0),0))*64,0),64)>0,MOD(ROUND(INDEX('Liste outils'!$H$6:$H$130,IFERROR(MATCH(12,Calcul!$M$60:$M$184,0),0))*64,0),64)/GCD(MOD(ROUND(INDEX('Liste outils'!$H$6:$H$130,IFERROR(MATCH(12,Calcul!$M$60:$M$184,0),0))*64,0),64),64)&"/"&64/GCD(MOD(ROUND(INDEX('Liste outils'!$H$6:$H$130,IFERROR(MATCH(12,Calcul!$M$60:$M$184,0),0))*64,0),64),64),IF(ROUND(INDEX('Liste outils'!$H$6:$H$130,IFERROR(MATCH(12,Calcul!$M$60:$M$184,0),0))*64,0)=0,"0",""))&""""))&" · "&FIXED(INDEX('Liste outils'!$H$6:$H$130,IFERROR(MATCH(12,Calcul!$M$60:$M$184,0),0)),4,TRUE())&" po · "&FIXED(INDEX('Liste outils'!$H$6:$H$130,IFERROR(MATCH(12,Calcul!$M$60:$M$184,0),0))*25.4,3,TRUE())&" mm"),"")) | E33: =IF(IFERROR(MATCH(12,Calcul!$M$60:$M$184,0),0)=0,"",INDEX('Liste outils'!$AB$6:$AB$130,IFERROR(MATCH(12,Calcul!$M$60:$M$184,0),0))&"") | F33: =IF(IFERROR(MATCH(12,Calcul!$M$60:$M$184,0),0)=0,"",INDEX('Liste outils'!$O$6:$O$130,IFERROR(MATCH(12,Calcul!$M$60:$M$184,0),0))&"") | G33: =IF(IFERROR(MATCH(12,Calcul!$M$60:$M$184,0),0)=0,"",INDEX('Liste outils'!$AC$6:$AC$130,IFERROR(MATCH(12,Calcul!$M$60:$M$184,0),0))&"")
A34: =IF(IFERROR(MATCH(13,Calcul!$M$60:$M$184,0),0)=0,"",INDEX('Liste outils'!$B$6:$B$130,IFERROR(MATCH(13,Calcul!$M$60:$M$184,0),0))&"") | B34: =IF(IFERROR(MATCH(13,Calcul!$M$60:$M$184,0),0)=0,"",INDEX('Liste outils'!$C$6:$C$130,IFERROR(MATCH(13,Calcul!$M$60:$M$184,0),0))&"") | C34: =IF(IFERROR(MATCH(13,Calcul!$M$60:$M$184,0),0)=0,"",INDEX('Liste outils'!$J$6:$J$130,IFERROR(MATCH(13,Calcul!$M$60:$M$184,0),0))&"") | D34: =IF(IFERROR(MATCH(13,Calcul!$M$60:$M$184,0),0)=0,"",IF(ISNUMBER(INDEX('Liste outils'!$H$6:$H$130,IFERROR(MATCH(13,Calcul!$M$60:$M$184,0),0))),IF(NOT(ISNUMBER(INDEX('Liste outils'!$H$6:$H$130,IFERROR(MATCH(13,Calcul!$M$60:$M$184,0),0)))),"",IF(NOT(ISNUMBER(INDEX('Liste outils'!$H$6:$H$130,IFERROR(MATCH(13,Calcul!$M$60:$M$184,0),0)))),"",IF(INDEX('Liste outils'!$H$6:$H$130,IFERROR(MATCH(13,Calcul!$M$60:$M$184,0),0))<=0,"",IF(ABS(INDEX('Liste outils'!$H$6:$H$130,IFERROR(MATCH(13,Calcul!$M$60:$M$184,0),0))*64-ROUND(INDEX('Liste outils'!$H$6:$H$130,IFERROR(MATCH(13,Calcul!$M$60:$M$184,0),0))*64,0))>0.0005,"≈ ","")&IF(INT(ROUND(INDEX('Liste outils'!$H$6:$H$130,IFERROR(MATCH(13,Calcul!$M$60:$M$184,0),0))*64,0)/64)>0,INT(ROUND(INDEX('Liste outils'!$H$6:$H$130,IFERROR(MATCH(13,Calcul!$M$60:$M$184,0),0))*64,0)/64)&IF(MOD(ROUND(INDEX('Liste outils'!$H$6:$H$130,IFERROR(MATCH(13,Calcul!$M$60:$M$184,0),0))*64,0),64)>0," ",""),"")&IF(MOD(ROUND(INDEX('Liste outils'!$H$6:$H$130,IFERROR(MATCH(13,Calcul!$M$60:$M$184,0),0))*64,0),64)>0,MOD(ROUND(INDEX('Liste outils'!$H$6:$H$130,IFERROR(MATCH(13,Calcul!$M$60:$M$184,0),0))*64,0),64)/GCD(MOD(ROUND(INDEX('Liste outils'!$H$6:$H$130,IFERROR(MATCH(13,Calcul!$M$60:$M$184,0),0))*64,0),64),64)&"/"&64/GCD(MOD(ROUND(INDEX('Liste outils'!$H$6:$H$130,IFERROR(MATCH(13,Calcul!$M$60:$M$184,0),0))*64,0),64),64),IF(ROUND(INDEX('Liste outils'!$H$6:$H$130,IFERROR(MATCH(13,Calcul!$M$60:$M$184,0),0))*64,0)=0,"0",""))&""""))&" · "&FIXED(INDEX('Liste outils'!$H$6:$H$130,IFERROR(MATCH(13,Calcul!$M$60:$M$184,0),0)),4,TRUE())&" po · "&FIXED(INDEX('Liste outils'!$H$6:$H$130,IFERROR(MATCH(13,Calcul!$M$60:$M$184,0),0))*25.4,3,TRUE())&" mm"),"")) | E34: =IF(IFERROR(MATCH(13,Calcul!$M$60:$M$184,0),0)=0,"",INDEX('Liste outils'!$AB$6:$AB$130,IFERROR(MATCH(13,Calcul!$M$60:$M$184,0),0))&"") | F34: =IF(IFERROR(MATCH(13,Calcul!$M$60:$M$184,0),0)=0,"",INDEX('Liste outils'!$O$6:$O$130,IFERROR(MATCH(13,Calcul!$M$60:$M$184,0),0))&"") | G34: =IF(IFERROR(MATCH(13,Calcul!$M$60:$M$184,0),0)=0,"",INDEX('Liste outils'!$AC$6:$AC$130,IFERROR(MATCH(13,Calcul!$M$60:$M$184,0),0))&"")
A35: =IF(IFERROR(MATCH(14,Calcul!$M$60:$M$184,0),0)=0,"",INDEX('Liste outils'!$B$6:$B$130,IFERROR(MATCH(14,Calcul!$M$60:$M$184,0),0))&"") | B35: =IF(IFERROR(MATCH(14,Calcul!$M$60:$M$184,0),0)=0,"",INDEX('Liste outils'!$C$6:$C$130,IFERROR(MATCH(14,Calcul!$M$60:$M$184,0),0))&"") | C35: =IF(IFERROR(MATCH(14,Calcul!$M$60:$M$184,0),0)=0,"",INDEX('Liste outils'!$J$6:$J$130,IFERROR(MATCH(14,Calcul!$M$60:$M$184,0),0))&"") | D35: =IF(IFERROR(MATCH(14,Calcul!$M$60:$M$184,0),0)=0,"",IF(ISNUMBER(INDEX('Liste outils'!$H$6:$H$130,IFERROR(MATCH(14,Calcul!$M$60:$M$184,0),0))),IF(NOT(ISNUMBER(INDEX('Liste outils'!$H$6:$H$130,IFERROR(MATCH(14,Calcul!$M$60:$M$184,0),0)))),"",IF(NOT(ISNUMBER(INDEX('Liste outils'!$H$6:$H$130,IFERROR(MATCH(14,Calcul!$M$60:$M$184,0),0)))),"",IF(INDEX('Liste outils'!$H$6:$H$130,IFERROR(MATCH(14,Calcul!$M$60:$M$184,0),0))<=0,"",IF(ABS(INDEX('Liste outils'!$H$6:$H$130,IFERROR(MATCH(14,Calcul!$M$60:$M$184,0),0))*64-ROUND(INDEX('Liste outils'!$H$6:$H$130,IFERROR(MATCH(14,Calcul!$M$60:$M$184,0),0))*64,0))>0.0005,"≈ ","")&IF(INT(ROUND(INDEX('Liste outils'!$H$6:$H$130,IFERROR(MATCH(14,Calcul!$M$60:$M$184,0),0))*64,0)/64)>0,INT(ROUND(INDEX('Liste outils'!$H$6:$H$130,IFERROR(MATCH(14,Calcul!$M$60:$M$184,0),0))*64,0)/64)&IF(MOD(ROUND(INDEX('Liste outils'!$H$6:$H$130,IFERROR(MATCH(14,Calcul!$M$60:$M$184,0),0))*64,0),64)>0," ",""),"")&IF(MOD(ROUND(INDEX('Liste outils'!$H$6:$H$130,IFERROR(MATCH(14,Calcul!$M$60:$M$184,0),0))*64,0),64)>0,MOD(ROUND(INDEX('Liste outils'!$H$6:$H$130,IFERROR(MATCH(14,Calcul!$M$60:$M$184,0),0))*64,0),64)/GCD(MOD(ROUND(INDEX('Liste outils'!$H$6:$H$130,IFERROR(MATCH(14,Calcul!$M$60:$M$184,0),0))*64,0),64),64)&"/"&64/GCD(MOD(ROUND(INDEX('Liste outils'!$H$6:$H$130,IFERROR(MATCH(14,Calcul!$M$60:$M$184,0),0))*64,0),64),64),IF(ROUND(INDEX('Liste outils'!$H$6:$H$130,IFERROR(MATCH(14,Calcul!$M$60:$M$184,0),0))*64,0)=0,"0",""))&""""))&" · "&FIXED(INDEX('Liste outils'!$H$6:$H$130,IFERROR(MATCH(14,Calcul!$M$60:$M$184,0),0)),4,TRUE())&" po · "&FIXED(INDEX('Liste outils'!$H$6:$H$130,IFERROR(MATCH(14,Calcul!$M$60:$M$184,0),0))*25.4,3,TRUE())&" mm"),"")) | E35: =IF(IFERROR(MATCH(14,Calcul!$M$60:$M$184,0),0)=0,"",INDEX('Liste outils'!$AB$6:$AB$130,IFERROR(MATCH(14,Calcul!$M$60:$M$184,0),0))&"") | F35: =IF(IFERROR(MATCH(14,Calcul!$M$60:$M$184,0),0)=0,"",INDEX('Liste outils'!$O$6:$O$130,IFERROR(MATCH(14,Calcul!$M$60:$M$184,0),0))&"") | G35: =IF(IFERROR(MATCH(14,Calcul!$M$60:$M$184,0),0)=0,"",INDEX('Liste outils'!$AC$6:$AC$130,IFERROR(MATCH(14,Calcul!$M$60:$M$184,0),0))&"")
A36: =IF(IFERROR(MATCH(15,Calcul!$M$60:$M$184,0),0)=0,"",INDEX('Liste outils'!$B$6:$B$130,IFERROR(MATCH(15,Calcul!$M$60:$M$184,0),0))&"") | B36: =IF(IFERROR(MATCH(15,Calcul!$M$60:$M$184,0),0)=0,"",INDEX('Liste outils'!$C$6:$C$130,IFERROR(MATCH(15,Calcul!$M$60:$M$184,0),0))&"") | C36: =IF(IFERROR(MATCH(15,Calcul!$M$60:$M$184,0),0)=0,"",INDEX('Liste outils'!$J$6:$J$130,IFERROR(MATCH(15,Calcul!$M$60:$M$184,0),0))&"") | D36: =IF(IFERROR(MATCH(15,Calcul!$M$60:$M$184,0),0)=0,"",IF(ISNUMBER(INDEX('Liste outils'!$H$6:$H$130,IFERROR(MATCH(15,Calcul!$M$60:$M$184,0),0))),IF(NOT(ISNUMBER(INDEX('Liste outils'!$H$6:$H$130,IFERROR(MATCH(15,Calcul!$M$60:$M$184,0),0)))),"",IF(NOT(ISNUMBER(INDEX('Liste outils'!$H$6:$H$130,IFERROR(MATCH(15,Calcul!$M$60:$M$184,0),0)))),"",IF(INDEX('Liste outils'!$H$6:$H$130,IFERROR(MATCH(15,Calcul!$M$60:$M$184,0),0))<=0,"",IF(ABS(INDEX('Liste outils'!$H$6:$H$130,IFERROR(MATCH(15,Calcul!$M$60:$M$184,0),0))*64-ROUND(INDEX('Liste outils'!$H$6:$H$130,IFERROR(MATCH(15,Calcul!$M$60:$M$184,0),0))*64,0))>0.0005,"≈ ","")&IF(INT(ROUND(INDEX('Liste outils'!$H$6:$H$130,IFERROR(MATCH(15,Calcul!$M$60:$M$184,0),0))*64,0)/64)>0,INT(ROUND(INDEX('Liste outils'!$H$6:$H$130,IFERROR(MATCH(15,Calcul!$M$60:$M$184,0),0))*64,0)/64)&IF(MOD(ROUND(INDEX('Liste outils'!$H$6:$H$130,IFERROR(MATCH(15,Calcul!$M$60:$M$184,0),0))*64,0),64)>0," ",""),"")&IF(MOD(ROUND(INDEX('Liste outils'!$H$6:$H$130,IFERROR(MATCH(15,Calcul!$M$60:$M$184,0),0))*64,0),64)>0,MOD(ROUND(INDEX('Liste outils'!$H$6:$H$130,IFERROR(MATCH(15,Calcul!$M$60:$M$184,0),0))*64,0),64)/GCD(MOD(ROUND(INDEX('Liste outils'!$H$6:$H$130,IFERROR(MATCH(15,Calcul!$M$60:$M$184,0),0))*64,0),64),64)&"/"&64/GCD(MOD(ROUND(INDEX('Liste outils'!$H$6:$H$130,IFERROR(MATCH(15,Calcul!$M$60:$M$184,0),0))*64,0),64),64),IF(ROUND(INDEX('Liste outils'!$H$6:$H$130,IFERROR(MATCH(15,Calcul!$M$60:$M$184,0),0))*64,0)=0,"0",""))&""""))&" · "&FIXED(INDEX('Liste outils'!$H$6:$H$130,IFERROR(MATCH(15,Calcul!$M$60:$M$184,0),0)),4,TRUE())&" po · "&FIXED(INDEX('Liste outils'!$H$6:$H$130,IFERROR(MATCH(15,Calcul!$M$60:$M$184,0),0))*25.4,3,TRUE())&" mm"),"")) | E36: =IF(IFERROR(MATCH(15,Calcul!$M$60:$M$184,0),0)=0,"",INDEX('Liste outils'!$AB$6:$AB$130,IFERROR(MATCH(15,Calcul!$M$60:$M$184,0),0))&"") | F36: =IF(IFERROR(MATCH(15,Calcul!$M$60:$M$184,0),0)=0,"",INDEX('Liste outils'!$O$6:$O$130,IFERROR(MATCH(15,Calcul!$M$60:$M$184,0),0))&"") | G36: =IF(IFERROR(MATCH(15,Calcul!$M$60:$M$184,0),0)=0,"",INDEX('Liste outils'!$AC$6:$AC$130,IFERROR(MATCH(15,Calcul!$M$60:$M$184,0),0))&"")
A37: =IF(IFERROR(MATCH(16,Calcul!$M$60:$M$184,0),0)=0,"",INDEX('Liste outils'!$B$6:$B$130,IFERROR(MATCH(16,Calcul!$M$60:$M$184,0),0))&"") | B37: =IF(IFERROR(MATCH(16,Calcul!$M$60:$M$184,0),0)=0,"",INDEX('Liste outils'!$C$6:$C$130,IFERROR(MATCH(16,Calcul!$M$60:$M$184,0),0))&"") | C37: =IF(IFERROR(MATCH(16,Calcul!$M$60:$M$184,0),0)=0,"",INDEX('Liste outils'!$J$6:$J$130,IFERROR(MATCH(16,Calcul!$M$60:$M$184,0),0))&"") | D37: =IF(IFERROR(MATCH(16,Calcul!$M$60:$M$184,0),0)=0,"",IF(ISNUMBER(INDEX('Liste outils'!$H$6:$H$130,IFERROR(MATCH(16,Calcul!$M$60:$M$184,0),0))),IF(NOT(ISNUMBER(INDEX('Liste outils'!$H$6:$H$130,IFERROR(MATCH(16,Calcul!$M$60:$M$184,0),0)))),"",IF(NOT(ISNUMBER(INDEX('Liste outils'!$H$6:$H$130,IFERROR(MATCH(16,Calcul!$M$60:$M$184,0),0)))),"",IF(INDEX('Liste outils'!$H$6:$H$130,IFERROR(MATCH(16,Calcul!$M$60:$M$184,0),0))<=0,"",IF(ABS(INDEX('Liste outils'!$H$6:$H$130,IFERROR(MATCH(16,Calcul!$M$60:$M$184,0),0))*64-ROUND(INDEX('Liste outils'!$H$6:$H$130,IFERROR(MATCH(16,Calcul!$M$60:$M$184,0),0))*64,0))>0.0005,"≈ ","")&IF(INT(ROUND(INDEX('Liste outils'!$H$6:$H$130,IFERROR(MATCH(16,Calcul!$M$60:$M$184,0),0))*64,0)/64)>0,INT(ROUND(INDEX('Liste outils'!$H$6:$H$130,IFERROR(MATCH(16,Calcul!$M$60:$M$184,0),0))*64,0)/64)&IF(MOD(ROUND(INDEX('Liste outils'!$H$6:$H$130,IFERROR(MATCH(16,Calcul!$M$60:$M$184,0),0))*64,0),64)>0," ",""),"")&IF(MOD(ROUND(INDEX('Liste outils'!$H$6:$H$130,IFERROR(MATCH(16,Calcul!$M$60:$M$184,0),0))*64,0),64)>0,MOD(ROUND(INDEX('Liste outils'!$H$6:$H$130,IFERROR(MATCH(16,Calcul!$M$60:$M$184,0),0))*64,0),64)/GCD(MOD(ROUND(INDEX('Liste outils'!$H$6:$H$130,IFERROR(MATCH(16,Calcul!$M$60:$M$184,0),0))*64,0),64),64)&"/"&64/GCD(MOD(ROUND(INDEX('Liste outils'!$H$6:$H$130,IFERROR(MATCH(16,Calcul!$M$60:$M$184,0),0))*64,0),64),64),IF(ROUND(INDEX('Liste outils'!$H$6:$H$130,IFERROR(MATCH(16,Calcul!$M$60:$M$184,0),0))*64,0)=0,"0",""))&""""))&" · "&FIXED(INDEX('Liste outils'!$H$6:$H$130,IFERROR(MATCH(16,Calcul!$M$60:$M$184,0),0)),4,TRUE())&" po · "&FIXED(INDEX('Liste outils'!$H$6:$H$130,IFERROR(MATCH(16,Calcul!$M$60:$M$184,0),0))*25.4,3,TRUE())&" mm"),"")) | E37: =IF(IFERROR(MATCH(16,Calcul!$M$60:$M$184,0),0)=0,"",INDEX('Liste outils'!$AB$6:$AB$130,IFERROR(MATCH(16,Calcul!$M$60:$M$184,0),0))&"") | F37: =IF(IFERROR(MATCH(16,Calcul!$M$60:$M$184,0),0)=0,"",INDEX('Liste outils'!$O$6:$O$130,IFERROR(MATCH(16,Calcul!$M$60:$M$184,0),0))&"") | G37: =IF(IFERROR(MATCH(16,Calcul!$M$60:$M$184,0),0)=0,"",INDEX('Liste outils'!$AC$6:$AC$130,IFERROR(MATCH(16,Calcul!$M$60:$M$184,0),0))&"")
A39: ="Outils de ta liste pour "&IF(C15<=0,"—",B15)&" ("&A15&")" -> Outils de ta liste pour 1/4" (1 cran en dessous)
A40: =IF(C15<=0,"",COUNT(Calcul!$N$60:$N$184)&" outil(s) de ce diamètre") -> 14 outil(s) de ce diamètre
A41: N° | B41: Type | C41: Direction | D41: LOC | E41: Emplacement | F41: N° fabricant | G41: Note
A42: =IF(IFERROR(MATCH(1,Calcul!$N$60:$N$184,0),0)=0,"",INDEX('Liste outils'!$B$6:$B$130,IFERROR(MATCH(1,Calcul!$N$60:$N$184,0),0))&"") -> I0023 | B42: =IF(IFERROR(MATCH(1,Calcul!$N$60:$N$184,0),0)=0,"",INDEX('Liste outils'!$C$6:$C$130,IFERROR(MATCH(1,Calcul!$N$60:$N$184,0),0))&"") -> Insert | C42: =IF(IFERROR(MATCH(1,Calcul!$N$60:$N$184,0),0)=0,"",INDEX('Liste outils'!$J$6:$J$130,IFERROR(MATCH(1,Calcul!$N$60:$N$184,0),0))&"") | D42: =IF(IFERROR(MATCH(1,Calcul!$N$60:$N$184,0),0)=0,"",IF(ISNUMBER(INDEX('Liste outils'!$H$6:$H$130,IFERROR(MATCH(1,Calcul!$N$60:$N$184,0),0))),IF(NOT(ISNUMBER(INDEX('Liste outils'!$H$6:$H$130,IFERROR(MATCH(1,Calcul!$N$60:$N$184,0),0)))),"",IF(NOT(ISNUMBER(INDEX('Liste outils'!$H$6:$H$130,IFERROR(MATCH(1,Calcul!$N$60:$N$184,0),0)))),"",IF(INDEX('Liste outils'!$H$6:$H$130,IFERROR(MATCH(1,Calcul!$N$60:$N$184,0),0))<=0,"",IF(ABS(INDEX('Liste outils'!$H$6:$H$130,IFERROR(MATCH(1,Calcul!$N$60:$N$184,0),0))*64-ROUND(INDEX('Liste outils'!$H$6:$H$130,IFERROR(MATCH(1,Calcul!$N$60:$N$184,0),0))*64,0))>0.0005,"≈ ","")&IF(INT(ROUND(INDEX('Liste outils'!$H$6:$H$130,IFERROR(MATCH(1,Calcul!$N$60:$N$184,0),0))*64,0)/64)>0,INT(ROUND(INDEX('Liste outils'!$H$6:$H$130,IFERROR(MATCH(1,Calcul!$N$60:$N$184,0),0))*64,0)/64)&IF(MOD(ROUND(INDEX('Liste outils'!$H$6:$H$130,IFERROR(MATCH(1,Calcul!$N$60:$N$184,0),0))*64,0),64)>0," ",""),"")&IF(MOD(ROUND(INDEX('Liste outils'!$H$6:$H$130,IFERROR(MATCH(1,Calcul!$N$60:$N$184,0),0))*64,0),64)>0,MOD(ROUND(INDEX('Liste outils'!$H$6:$H$130,IFERROR(MATCH(1,Calcul!$N$60:$N$184,0),0))*64,0),64)/GCD(MOD(ROUND(INDEX('Liste outils'!$H$6:$H$130,IFERROR(MATCH(1,Calcul!$N$60:$N$184,0),0))*64,0),64),64)&"/"&64/GCD(MOD(ROUND(INDEX('Liste outils'!$H$6:$H$130,IFERROR(MATCH(1,Calcul!$N$60:$N$184,0),0))*64,0),64),64),IF(ROUND(INDEX('Liste outils'!$H$6:$H$130,IFERROR(MATCH(1,Calcul!$N$60:$N$184,0),0))*64,0)=0,"0",""))&""""))&" · "&FIXED(INDEX('Liste outils'!$H$6:$H$130,IFERROR(MATCH(1,Calcul!$N$60:$N$184,0),0)),4,TRUE())&" po · "&FIXED(INDEX('Liste outils'!$H$6:$H$130,IFERROR(MATCH(1,Calcul!$N$60:$N$184,0),0))*25.4,3,TRUE())&" mm"),"")) -> ≈ 1/4" · 0.2539 po · 6.449 mm | E42: =IF(IFERROR(MATCH(1,Calcul!$N$60:$N$184,0),0)=0,"",INDEX('Liste outils'!$AB$6:$AB$130,IFERROR(MATCH(1,Calcul!$N$60:$N$184,0),0))&"") -> A-2-C-4 | F42: =IF(IFERROR(MATCH(1,Calcul!$N$60:$N$184,0),0)=0,"",INDEX('Liste outils'!$O$6:$O$130,IFERROR(MATCH(1,Calcul!$N$60:$N$184,0),0))&"") -> CPMT060204FP | G42: =IF(IFERROR(MATCH(1,Calcul!$N$60:$N$184,0),0)=0,"",INDEX('Liste outils'!$AC$6:$AC$130,IFERROR(MATCH(1,Calcul!$N$60:$N$184,0),0))&"") -> CPMT2151FP
A43: =IF(IFERROR(MATCH(2,Calcul!$N$60:$N$184,0),0)=0,"",INDEX('Liste outils'!$B$6:$B$130,IFERROR(MATCH(2,Calcul!$N$60:$N$184,0),0))&"") -> I0024 | B43: =IF(IFERROR(MATCH(2,Calcul!$N$60:$N$184,0),0)=0,"",INDEX('Liste outils'!$C$6:$C$130,IFERROR(MATCH(2,Calcul!$N$60:$N$184,0),0))&"") -> Insert | C43: =IF(IFERROR(MATCH(2,Calcul!$N$60:$N$184,0),0)=0,"",INDEX('Liste outils'!$J$6:$J$130,IFERROR(MATCH(2,Calcul!$N$60:$N$184,0),0))&"") | D43: =IF(IFERROR(MATCH(2,Calcul!$N$60:$N$184,0),0)=0,"",IF(ISNUMBER(INDEX('Liste outils'!$H$6:$H$130,IFERROR(MATCH(2,Calcul!$N$60:$N$184,0),0))),IF(NOT(ISNUMBER(INDEX('Liste outils'!$H$6:$H$130,IFERROR(MATCH(2,Calcul!$N$60:$N$184,0),0)))),"",IF(NOT(ISNUMBER(INDEX('Liste outils'!$H$6:$H$130,IFERROR(MATCH(2,Calcul!$N$60:$N$184,0),0)))),"",IF(INDEX('Liste outils'!$H$6:$H$130,IFERROR(MATCH(2,Calcul!$N$60:$N$184,0),0))<=0,"",IF(ABS(INDEX('Liste outils'!$H$6:$H$130,IFERROR(MATCH(2,Calcul!$N$60:$N$184,0),0))*64-ROUND(INDEX('Liste outils'!$H$6:$H$130,IFERROR(MATCH(2,Calcul!$N$60:$N$184,0),0))*64,0))>0.0005,"≈ ","")&IF(INT(ROUND(INDEX('Liste outils'!$H$6:$H$130,IFERROR(MATCH(2,Calcul!$N$60:$N$184,0),0))*64,0)/64)>0,INT(ROUND(INDEX('Liste outils'!$H$6:$H$130,IFERROR(MATCH(2,Calcul!$N$60:$N$184,0),0))*64,0)/64)&IF(MOD(ROUND(INDEX('Liste outils'!$H$6:$H$130,IFERROR(MATCH(2,Calcul!$N$60:$N$184,0),0))*64,0),64)>0," ",""),"")&IF(MOD(ROUND(INDEX('Liste outils'!$H$6:$H$130,IFERROR(MATCH(2,Calcul!$N$60:$N$184,0),0))*64,0),64)>0,MOD(ROUND(INDEX('Liste outils'!$H$6:$H$130,IFERROR(MATCH(2,Calcul!$N$60:$N$184,0),0))*64,0),64)/GCD(MOD(ROUND(INDEX('Liste outils'!$H$6:$H$130,IFERROR(MATCH(2,Calcul!$N$60:$N$184,0),0))*64,0),64),64)&"/"&64/GCD(MOD(ROUND(INDEX('Liste outils'!$H$6:$H$130,IFERROR(MATCH(2,Calcul!$N$60:$N$184,0),0))*64,0),64),64),IF(ROUND(INDEX('Liste outils'!$H$6:$H$130,IFERROR(MATCH(2,Calcul!$N$60:$N$184,0),0))*64,0)=0,"0",""))&""""))&" · "&FIXED(INDEX('Liste outils'!$H$6:$H$130,IFERROR(MATCH(2,Calcul!$N$60:$N$184,0),0)),4,TRUE())&" po · "&FIXED(INDEX('Liste outils'!$H$6:$H$130,IFERROR(MATCH(2,Calcul!$N$60:$N$184,0),0))*25.4,3,TRUE())&" mm"),"")) -> ≈ 1/4" · 0.2539 po · 6.449 mm | E43: =IF(IFERROR(MATCH(2,Calcul!$N$60:$N$184,0),0)=0,"",INDEX('Liste outils'!$AB$6:$AB$130,IFERROR(MATCH(2,Calcul!$N$60:$N$184,0),0))&"") -> A-2-F-4 | F43: =IF(IFERROR(MATCH(2,Calcul!$N$60:$N$184,0),0)=0,"",INDEX('Liste outils'!$O$6:$O$130,IFERROR(MATCH(2,Calcul!$N$60:$N$184,0),0))&"") -> CCMT060204FP | G43: =IF(IFERROR(MATCH(2,Calcul!$N$60:$N$184,0),0)=0,"",INDEX('Liste outils'!$AC$6:$AC$130,IFERROR(MATCH(2,Calcul!$N$60:$N$184,0),0))&"") -> Material Number 7167775, ANSI CCMT2151FP
A44: =IF(IFERROR(MATCH(3,Calcul!$N$60:$N$184,0),0)=0,"",INDEX('Liste outils'!$B$6:$B$130,IFERROR(MATCH(3,Calcul!$N$60:$N$184,0),0))&"") -> EM0001 | B44: =IF(IFERROR(MATCH(3,Calcul!$N$60:$N$184,0),0)=0,"",INDEX('Liste outils'!$C$6:$C$130,IFERROR(MATCH(3,Calcul!$N$60:$N$184,0),0))&"") -> End Mill | C44: =IF(IFERROR(MATCH(3,Calcul!$N$60:$N$184,0),0)=0,"",INDEX('Liste outils'!$J$6:$J$130,IFERROR(MATCH(3,Calcul!$N$60:$N$184,0),0))&"") | D44: =IF(IFERROR(MATCH(3,Calcul!$N$60:$N$184,0),0)=0,"",IF(ISNUMBER(INDEX('Liste outils'!$H$6:$H$130,IFERROR(MATCH(3,Calcul!$N$60:$N$184,0),0))),IF(NOT(ISNUMBER(INDEX('Liste outils'!$H$6:$H$130,IFERROR(MATCH(3,Calcul!$N$60:$N$184,0),0)))),"",IF(NOT(ISNUMBER(INDEX('Liste outils'!$H$6:$H$130,IFERROR(MATCH(3,Calcul!$N$60:$N$184,0),0)))),"",IF(INDEX('Liste outils'!$H$6:$H$130,IFERROR(MATCH(3,Calcul!$N$60:$N$184,0),0))<=0,"",IF(ABS(INDEX('Liste outils'!$H$6:$H$130,IFERROR(MATCH(3,Calcul!$N$60:$N$184,0),0))*64-ROUND(INDEX('Liste outils'!$H$6:$H$130,IFERROR(MATCH(3,Calcul!$N$60:$N$184,0),0))*64,0))>0.0005,"≈ ","")&IF(INT(ROUND(INDEX('Liste outils'!$H$6:$H$130,IFERROR(MATCH(3,Calcul!$N$60:$N$184,0),0))*64,0)/64)>0,INT(ROUND(INDEX('Liste outils'!$H$6:$H$130,IFERROR(MATCH(3,Calcul!$N$60:$N$184,0),0))*64,0)/64)&IF(MOD(ROUND(INDEX('Liste outils'!$H$6:$H$130,IFERROR(MATCH(3,Calcul!$N$60:$N$184,0),0))*64,0),64)>0," ",""),"")&IF(MOD(ROUND(INDEX('Liste outils'!$H$6:$H$130,IFERROR(MATCH(3,Calcul!$N$60:$N$184,0),0))*64,0),64)>0,MOD(ROUND(INDEX('Liste outils'!$H$6:$H$130,IFERROR(MATCH(3,Calcul!$N$60:$N$184,0),0))*64,0),64)/GCD(MOD(ROUND(INDEX('Liste outils'!$H$6:$H$130,IFERROR(MATCH(3,Calcul!$N$60:$N$184,0),0))*64,0),64),64)&"/"&64/GCD(MOD(ROUND(INDEX('Liste outils'!$H$6:$H$130,IFERROR(MATCH(3,Calcul!$N$60:$N$184,0),0))*64,0),64),64),IF(ROUND(INDEX('Liste outils'!$H$6:$H$130,IFERROR(MATCH(3,Calcul!$N$60:$N$184,0),0))*64,0)=0,"0",""))&""""))&" · "&FIXED(INDEX('Liste outils'!$H$6:$H$130,IFERROR(MATCH(3,Calcul!$N$60:$N$184,0),0)),4,TRUE())&" po · "&FIXED(INDEX('Liste outils'!$H$6:$H$130,IFERROR(MATCH(3,Calcul!$N$60:$N$184,0),0))*25.4,3,TRUE())&" mm"),"")) -> 3/8" · 0.3750 po · 9.525 mm | E44: =IF(IFERROR(MATCH(3,Calcul!$N$60:$N$184,0),0)=0,"",INDEX('Liste outils'!$AB$6:$AB$130,IFERROR(MATCH(3,Calcul!$N$60:$N$184,0),0))&"") -> A-2-A-3 | F44: =IF(IFERROR(MATCH(3,Calcul!$N$60:$N$184,0),0)=0,"",INDEX('Liste outils'!$O$6:$O$130,IFERROR(MATCH(3,Calcul!$N$60:$N$184,0),0))&"") -> DMASOL-230926 | G44: =IF(IFERROR(MATCH(3,Calcul!$N$60:$N$184,0),0)=0,"",INDEX('Liste outils'!$AC$6:$AC$130,IFERROR(MATCH(3,Calcul!$N$60:$N$184,0),0))&"") -> 45º Chamfer End
A45: =IF(IFERROR(MATCH(4,Calcul!$N$60:$N$184,0),0)=0,"",INDEX('Liste outils'!$B$6:$B$130,IFERROR(MATCH(4,Calcul!$N$60:$N$184,0),0))&"") -> EM0004 | B45: =IF(IFERROR(MATCH(4,Calcul!$N$60:$N$184,0),0)=0,"",INDEX('Liste outils'!$C$6:$C$130,IFERROR(MATCH(4,Calcul!$N$60:$N$184,0),0))&"") -> End Mill | C45: =IF(IFERROR(MATCH(4,Calcul!$N$60:$N$184,0),0)=0,"",INDEX('Liste outils'!$J$6:$J$130,IFERROR(MATCH(4,Calcul!$N$60:$N$184,0),0))&"") -> Upcut | D45: =IF(IFERROR(MATCH(4,Calcul!$N$60:$N$184,0),0)=0,"",IF(ISNUMBER(INDEX('Liste outils'!$H$6:$H$130,IFERROR(MATCH(4,Calcul!$N$60:$N$184,0),0))),IF(NOT(ISNUMBER(INDEX('Liste outils'!$H$6:$H$130,IFERROR(MATCH(4,Calcul!$N$60:$N$184,0),0)))),"",IF(NOT(ISNUMBER(INDEX('Liste outils'!$H$6:$H$130,IFERROR(MATCH(4,Calcul!$N$60:$N$184,0),0)))),"",IF(INDEX('Liste outils'!$H$6:$H$130,IFERROR(MATCH(4,Calcul!$N$60:$N$184,0),0))<=0,"",IF(ABS(INDEX('Liste outils'!$H$6:$H$130,IFERROR(MATCH(4,Calcul!$N$60:$N$184,0),0))*64-ROUND(INDEX('Liste outils'!$H$6:$H$130,IFERROR(MATCH(4,Calcul!$N$60:$N$184,0),0))*64,0))>0.0005,"≈ ","")&IF(INT(ROUND(INDEX('Liste outils'!$H$6:$H$130,IFERROR(MATCH(4,Calcul!$N$60:$N$184,0),0))*64,0)/64)>0,INT(ROUND(INDEX('Liste outils'!$H$6:$H$130,IFERROR(MATCH(4,Calcul!$N$60:$N$184,0),0))*64,0)/64)&IF(MOD(ROUND(INDEX('Liste outils'!$H$6:$H$130,IFERROR(MATCH(4,Calcul!$N$60:$N$184,0),0))*64,0),64)>0," ",""),"")&IF(MOD(ROUND(INDEX('Liste outils'!$H$6:$H$130,IFERROR(MATCH(4,Calcul!$N$60:$N$184,0),0))*64,0),64)>0,MOD(ROUND(INDEX('Liste outils'!$H$6:$H$130,IFERROR(MATCH(4,Calcul!$N$60:$N$184,0),0))*64,0),64)/GCD(MOD(ROUND(INDEX('Liste outils'!$H$6:$H$130,IFERROR(MATCH(4,Calcul!$N$60:$N$184,0),0))*64,0),64),64)&"/"&64/GCD(MOD(ROUND(INDEX('Liste outils'!$H$6:$H$130,IFERROR(MATCH(4,Calcul!$N$60:$N$184,0),0))*64,0),64),64),IF(ROUND(INDEX('Liste outils'!$H$6:$H$130,IFERROR(MATCH(4,Calcul!$N$60:$N$184,0),0))*64,0)=0,"0",""))&""""))&" · "&FIXED(INDEX('Liste outils'!$H$6:$H$130,IFERROR(MATCH(4,Calcul!$N$60:$N$184,0),0)),4,TRUE())&" po · "&FIXED(INDEX('Liste outils'!$H$6:$H$130,IFERROR(MATCH(4,Calcul!$N$60:$N$184,0),0))*25.4,3,TRUE())&" mm"),"")) -> 3/8" · 0.3750 po · 9.525 mm | E45: =IF(IFERROR(MATCH(4,Calcul!$N$60:$N$184,0),0)=0,"",INDEX('Liste outils'!$AB$6:$AB$130,IFERROR(MATCH(4,Calcul!$N$60:$N$184,0),0))&"") -> A-1-A-3 | F45: =IF(IFERROR(MATCH(4,Calcul!$N$60:$N$184,0),0)=0,"",INDEX('Liste outils'!$O$6:$O$130,IFERROR(MATCH(4,Calcul!$N$60:$N$184,0),0))&"") -> 63-774 | G45: =IF(IFERROR(MATCH(4,Calcul!$N$60:$N$184,0),0)=0,"",INDEX('Liste outils'!$AC$6:$AC$130,IFERROR(MATCH(4,Calcul!$N$60:$N$184,0),0))&"") -> ARMTEC
A46: =IF(IFERROR(MATCH(5,Calcul!$N$60:$N$184,0),0)=0,"",INDEX('Liste outils'!$B$6:$B$130,IFERROR(MATCH(5,Calcul!$N$60:$N$184,0),0))&"") -> EM0008 | B46: =IF(IFERROR(MATCH(5,Calcul!$N$60:$N$184,0),0)=0,"",INDEX('Liste outils'!$C$6:$C$130,IFERROR(MATCH(5,Calcul!$N$60:$N$184,0),0))&"") -> End Mill | C46: =IF(IFERROR(MATCH(5,Calcul!$N$60:$N$184,0),0)=0,"",INDEX('Liste outils'!$J$6:$J$130,IFERROR(MATCH(5,Calcul!$N$60:$N$184,0),0))&"") -> Upcut | D46: =IF(IFERROR(MATCH(5,Calcul!$N$60:$N$184,0),0)=0,"",IF(ISNUMBER(INDEX('Liste outils'!$H$6:$H$130,IFERROR(MATCH(5,Calcul!$N$60:$N$184,0),0))),IF(NOT(ISNUMBER(INDEX('Liste outils'!$H$6:$H$130,IFERROR(MATCH(5,Calcul!$N$60:$N$184,0),0)))),"",IF(NOT(ISNUMBER(INDEX('Liste outils'!$H$6:$H$130,IFERROR(MATCH(5,Calcul!$N$60:$N$184,0),0)))),"",IF(INDEX('Liste outils'!$H$6:$H$130,IFERROR(MATCH(5,Calcul!$N$60:$N$184,0),0))<=0,"",IF(ABS(INDEX('Liste outils'!$H$6:$H$130,IFERROR(MATCH(5,Calcul!$N$60:$N$184,0),0))*64-ROUND(INDEX('Liste outils'!$H$6:$H$130,IFERROR(MATCH(5,Calcul!$N$60:$N$184,0),0))*64,0))>0.0005,"≈ ","")&IF(INT(ROUND(INDEX('Liste outils'!$H$6:$H$130,IFERROR(MATCH(5,Calcul!$N$60:$N$184,0),0))*64,0)/64)>0,INT(ROUND(INDEX('Liste outils'!$H$6:$H$130,IFERROR(MATCH(5,Calcul!$N$60:$N$184,0),0))*64,0)/64)&IF(MOD(ROUND(INDEX('Liste outils'!$H$6:$H$130,IFERROR(MATCH(5,Calcul!$N$60:$N$184,0),0))*64,0),64)>0," ",""),"")&IF(MOD(ROUND(INDEX('Liste outils'!$H$6:$H$130,IFERROR(MATCH(5,Calcul!$N$60:$N$184,0),0))*64,0),64)>0,MOD(ROUND(INDEX('Liste outils'!$H$6:$H$130,IFERROR(MATCH(5,Calcul!$N$60:$N$184,0),0))*64,0),64)/GCD(MOD(ROUND(INDEX('Liste outils'!$H$6:$H$130,IFERROR(MATCH(5,Calcul!$N$60:$N$184,0),0))*64,0),64),64)&"/"&64/GCD(MOD(ROUND(INDEX('Liste outils'!$H$6:$H$130,IFERROR(MATCH(5,Calcul!$N$60:$N$184,0),0))*64,0),64),64),IF(ROUND(INDEX('Liste outils'!$H$6:$H$130,IFERROR(MATCH(5,Calcul!$N$60:$N$184,0),0))*64,0)=0,"0",""))&""""))&" · "&FIXED(INDEX('Liste outils'!$H$6:$H$130,IFERROR(MATCH(5,Calcul!$N$60:$N$184,0),0)),4,TRUE())&" po · "&FIXED(INDEX('Liste outils'!$H$6:$H$130,IFERROR(MATCH(5,Calcul!$N$60:$N$184,0),0))*25.4,3,TRUE())&" mm"),"")) -> 3/4" · 0.7500 po · 19.050 mm | E46: =IF(IFERROR(MATCH(5,Calcul!$N$60:$N$184,0),0)=0,"",INDEX('Liste outils'!$AB$6:$AB$130,IFERROR(MATCH(5,Calcul!$N$60:$N$184,0),0))&"") -> A-1-B-3 | F46: =IF(IFERROR(MATCH(5,Calcul!$N$60:$N$184,0),0)=0,"",INDEX('Liste outils'!$O$6:$O$130,IFERROR(MATCH(5,Calcul!$N$60:$N$184,0),0))&"") -> 63-725 | G46: =IF(IFERROR(MATCH(5,Calcul!$N$60:$N$184,0),0)=0,"",INDEX('Liste outils'!$AC$6:$AC$130,IFERROR(MATCH(5,Calcul!$N$60:$N$184,0),0))&"")
...

Sheet Avances
A1: Vitesses et avances
A2: Choisis dans les cellules jaunes. Les 5 meilleurs outils de ta liste s'affichent en dessous.
A4: 1. Matériau | B4: Polycarbonate
A5: 2. Type de travail | B5: Détourage / profil
A6: Direction préférée | B6: Upcut | C6: ← pour détourage et trous seulement
A7: 3. Épaisseur à couper | B7: 1/2 | C7: ← ex. 1/2, 0.75, 12
A8: Unité de l'épaisseur | B8: Fraction | C8: =IF(Calcul!$I$10>0,"Épaisseur : "&IF(NOT(ISNUMBER(Calcul!$I$10)),"",IF(NOT(ISNUMBER(Calcul!$I$10)),"",IF(Calcul!$I$10<=0,"",IF(ABS(Calcul!$I$10*64-ROUND(Calcul!$I$10*64,0))>0.0005,"≈ ","")&IF(INT(ROUND(Calcul!$I$10*64,0)/64)>0,INT(ROUND(Calcul!$I$10*64,0)/64)&IF(MOD(ROUND(Calcul!$I$10*64,0),64)>0," ",""),"")&IF(MOD(ROUND(Calcul!$I$10*64,0),64)>0,MOD(ROUND(Calcul!$I$10*64,0),64)/GCD(MOD(ROUND(Calcul!$I$10*64,0),64),64)&"/"&64/GCD(MOD(ROUND(Calcul!$I$10*64,0),64),64),IF(ROUND(Calcul!$I$10*64,0)=0,"0",""))&""""))&" · "&FIXED(Calcul!$I$10,4,TRUE())&" po · "&FIXED(Calcul!$I$10*25.4,3,TRUE())&" mm"),"Entre une épaisseur") -> Épaisseur : 1/2" · 0.5000 po · 12.700 mm
A10: Les 5 meilleurs outils de ta liste
A11: =IF(Calcul!$I$10>0,"Fraises dont la LOC couvre l'épaisseur, une par diamètre d'abord, puis classées. Passes : jamais plus profond que le diamètre de l'outil.","Entre l'épaisseur pour vérifier la LOC et calculer les passes.") -> Fraises dont la LOC couvre l'épaisseur, une par diamètre d'abord, puis classées. Passes : jamais plus profond que le diamètre de l'outil.
A13: Rang | B13: Statut | C13: Outil | D13: Direction | E13: Ø | F13: LOC | G13: LOC − épaisseur | H13: Passes | I13: Profondeur / passe | J13: RPM atelier | K13: Avance atelier (po/min) | L13: Avance atelier (mm/min) | M13: Chipload (po) | N13: Chipload (mm) | O13: RPM Onsrud | P13: Avance Onsrud (po/min) | Q13: Avance Onsrud (mm/min) | R13: Série Onsrud | S13: Reco Onsrud | T13: Habitude atelier | U13: Emplacement | V13: Note
